Workbook

Sheet Sheet1
A1: ID | B1: , | C1: ALTX | D1: , | E1: ALARM_TEXT_KOREA | F1: , | G1: ALARM_TEXT_CHINA | H1: , | I1: ALARM_TEXT_ENGLISH | J1: , | K1: ALARM_TEXT_VIETNAM | L1: , | M1: ALARM_ACTION_TEXT_KOREA | N1: , | O1: ALARM_ACTION_TEXT_CHINA | P1: , | Q1: ALARM_ACTION_TEXT_ENGLIST | R1: , | S1: ALARM_ACTION_TEXT_VIETNAM | T1: , | U1: LEVEL | V1: , | W1: UNIT | X1: , | Y1: BOX_TYPE | Z1: , | AA1: BOX_RECTANGLE_X | AB1: , | AC1: BOX_RECTANGLE_Y | AD1: , | AE1: BOX_RECTANGLE_WIDTH | AF1: , | AG1: BOX_RECTANGLE_HEIGHT | AJ1: ID Base | AK1: ID Offset | AL1: ID | AM1: ALTX
A2: =AL2 -> 10000 | B2: , | C2: EM_UPPER_EQUIPMENT_N_EMERGENCY_STATE | D2: , | E2: 상류설비에서 EMERGENCY가 발생했습니다 | F2: , | G2: UPPER_EQUIPMENT_EMERGENCY_SIGNAL_ON | H2: , | I2: UPPER_EQUIPMENT_EMERGENCY_SIGNAL_ON | J2: , | K2: UPPER_EQUIPMENT_EMERGENCY_SIGNAL_ON | L2: , | M2: 전 공정 설비 상태 확인해주세요. | N2: , | O2: CHECK THE STATUS OF THE UPPER EQUIPMENT. | P2: , | Q2: CHECK THE STATUS OF THE UPPER EQUIPMENT. | R2: , | S2: Hãy kiểm tra tình trạng thiết bị ở công đoạn trước | T2: , | U2: HEAVY | V2: , | W2: LOAD_EQ_TO_EQ | X2: , | Y2: SQUARE | Z2: , | AA2: 0.01605137 | AB2: , | AC2: 0.02994792 | AD2: , | AE2: 0.04815409 | AF2: , | AG2: 0.9401042 | AJ2: =VLOOKUP(Sheet1!W2,'알람 범위'!$D$2:$F$45,3,FALSE) -> 10000 | AK2: 0 | AL2: =AJ2+AK2 -> 10000 | AM2: =C2 -> EM_UPPER_EQUIPMENT_N_EMERGENCY_STATE
A3: =AL3 -> 10001 | B3: , | C3: EM_UPPER_EQUIPMENT_DOOR_OPEN | D3: , | E3: 상류설비에 DOOR가 열렸습니다 | F3: , | G3: UPPER_EQUIPMENT_DOOR_OPEN | H3: , | I3: UPPER_EQUIPMENT_DOOR_OPEN | J3: , | K3: UPPER_EQUIPMENT_DOOR_OPEN | L3: , | M3: 전 공정 설비 상태 확인해주세요. | N3: , | O3: CHECK THE STATUS OF THE UPPER EQUIPMENT. | P3: , | Q3: CHECK THE STATUS OF THE UPPER EQUIPMENT. | R3: , | S3: Hãy kiểm tra tình trạng thiết bị ở công đoạn trước | T3: , | U3: LIGHT | V3: , | W3: LOAD_EQ_TO_EQ | X3: , | Y3: SQUARE | Z3: , | AA3: 0.01605137 | AB3: , | AC3: 0.02994792 | AD3: , | AE3: 0.04815409 | AF3: , | AG3: 0.9401042 | AJ3: =VLOOKUP(Sheet1!W3,'알람 범위'!$D$2:$F$45,3,FALSE) -> 10000 | AK3: 1 | AL3: =AJ3+AK3 -> 10001 | AM3: =C3 -> EM_UPPER_EQUIPMENT_DOOR_OPEN
A4: =AL4 -> 10500 | B4: , | C4: MO_IN_SHUTTLE_X1_HOME_MOTION | D4: , | E4: IN셔틀 X1축이 홈 동작 진행에 실패 했습니다 | F4: , | G4: IN_SHUTTLE_X1_AXIS_HOME_MOTION_FAILED | H4: , | I4: IN_SHUTTLE_X1_AXIS_HOME_MOTION_FAILED | J4: , | K4: IN_SHUTTLE trục X1 HOME không hoạt động | L4: , | M4: IN셔틀 X1축 드라이버 상태 확인 후 홈 동작을 수행하세요. | N4: , | O4: CHECK THE DRIVER STATUS OF THE IN SHUTTLE X1 AXIS AND THEN HOME OPERATION. | P4: , | Q4: CHECK THE DRIVER STATUS OF THE IN SHUTTLE X1 AXIS AND THEN HOME OPERATION. | R4: , | S4: Sau khi kiểm tra tình trạng DRIVER trục X1 - IN SHUTTLE hãy tiến hành chạy HOME . | T4: , | U4: HEAVY | V4: , | W4: IN_SHUTTLE | X4: , | Y4: SQUARE | Z4: , | AA4: 0.0176565 | AB4: , | AC4: 0.453125 | AD4: , | AE4: 0.5184591 | AF4: , | AG4: 0.1315104 | AJ4: =VLOOKUP(Sheet1!W4,'알람 범위'!$D$2:$F$45,3,FALSE) -> 10500 | AK4: 0 | AL4: =AJ4+AK4 -> 10500 | AM4: =C4 -> MO_IN_SHUTTLE_X1_HOME_MOTION
A5: =AL5 -> 10501 | B5: , | C5: MO_IN_SHUTTLE_X1_LOAD_MOVE | D5: , | E5: IN셔틀 X1축 로드 위치 이동에 실패 했습니다 (상류설비 위치) | F5: , | G5: IN_SHUTTLE_X1_AXIS_LOAD_POSITION_MOVE_FAILED (UPPER-EQUIPMENT POSITION) | H5: , | I5: IN_SHUTTLE_X1_AXIS_LOAD_POSITION_MOVE_FAILED (UPPER-EQUIPMENT POSITION) | J5: , | K5: IN_SHUTTLE trục X1 không thể di chuyển vị trí LOAD (UPPER-EQUIPMENT POSITION) | L5: , | M5: IN셔틀 X1축 드라이버 상태 확인해주세요. | N5: , | O5: CHECK THE DRIVER STATUS OF THE IN SHUTTLE X1 AXIS. | P5: , | Q5: CHECK THE DRIVER STATUS OF THE IN SHUTTLE X1 AXIS. | R5: , | S5: Hãy kiểm tra DRIVER trục X1 - IN SHUTTLE. | T5: , | U5: HEAVY | V5: , | W5: IN_SHUTTLE | X5: , | Y5: SQUARE | Z5: , | AA5: 0.0176565 | AB5: , | AC5: 0.453125 | AD5: , | AE5: 0.5184591 | AF5: , | AG5: 0.1315104 | AJ5: =VLOOKUP(Sheet1!W5,'알람 범위'!$D$2:$F$45,3,FALSE) -> 10500 | AK5: 1 | AL5: =AJ5+AK5 -> 10501 | AM5: =C5 -> MO_IN_SHUTTLE_X1_LOAD_MOVE
A6: =AL6 -> 10502 | B6: , | C6: MO_IN_SHUTTLE_X1_SCAN_START_WAIT_MOVE | D6: , | E6: IN셔틀 X1축 스캔 시작 대기 위치 이동에 실패 했습니다 | F6: , | G6: IN_SHUTTLE_X1_AXIS_SCAN_START_WAIT_POSITION_MOVE_FAILED | H6: , | I6: IN_SHUTTLE_X1_AXIS_SCAN_START_WAIT_POSITION_MOVE_FAILED | J6: , | K6: IN_SHUTTLE trục X1 không thể di chuyển vị trí SCAN START WAIT | L6: , | M6: IN셔틀 X1축 드라이버 상태 확인해주세요. | N6: , | O6: CHECK THE DRIVER STATUS OF THE IN SHUTTLE X1 AXIS. | P6: , | Q6: CHECK THE DRIVER STATUS OF THE IN SHUTTLE X1 AXIS. | R6: , | S6: Hãy kiểm tra DRIVER trục X1 - IN SHUTTLE. | T6: , | U6: HEAVY | V6: , | W6: IN_SHUTTLE | X6: , | Y6: SQUARE | Z6: , | AA6: 0.0176565 | AB6: , | AC6: 0.453125 | AD6: , | AE6: 0.5184591 | AF6: , | AG6: 0.1315104 | AJ6: =VLOOKUP(Sheet1!W6,'알람 범위'!$D$2:$F$45,3,FALSE) -> 10500 | AK6: 2 | AL6: =AJ6+AK6 -> 10502 | AM6: =C6 -> MO_IN_SHUTTLE_X1_SCAN_START_WAIT_MOVE
A7: =AL7 -> 10503 | B7: , | C7: MO_IN_SHUTTLE_X1_SCAN_TRIGGER_START_MOVE | D7: , | E7: IN셔틀 X1축 스캔 트리거 시작 위치 이동에 실패 했습니다 | F7: , | G7: IN_SHUTTLE_X1_AXIS_SCAN_TRIGGER_START_POSITION_MOVE_FAILED | H7: , | I7: IN_SHUTTLE_X1_AXIS_SCAN_TRIGGER_START_POSITION_MOVE_FAILED | J7: , | K7: IN_SHUTTLE trục X1 không thể di chuyển vị trí SCAN TRIGGER START | L7: , | M7: IN셔틀 X1축 드라이버 상태 확인해주세요. | N7: , | O7: CHECK THE DRIVER STATUS OF THE IN SHUTTLE X1 AXIS. | P7: , | Q7: CHECK THE DRIVER STATUS OF THE IN SHUTTLE X1 AXIS. | R7: , | S7: Hãy kiểm tra DRIVER trục X1 - IN SHUTTLE. | T7: , | U7: HEAVY | V7: , | W7: IN_SHUTTLE | X7: , | Y7: SQUARE | Z7: , | AA7: 0.0176565 | AB7: , | AC7: 0.453125 | AD7: , | AE7: 0.5184591 | AF7: , | AG7: 0.1315104 | AJ7: =VLOOKUP(Sheet1!W7,'알람 범위'!$D$2:$F$45,3,FALSE) -> 10500 | AK7: 3 | AL7: =AJ7+AK7 -> 10503 | AM7: =C7 -> MO_IN_SHUTTLE_X1_SCAN_TRIGGER_START_MOVE
A8: =AL8 -> 10504 | B8: , | C8: MO_IN_SHUTTLE_X1_SCAN_TRIGGER_END_MOVE | D8: , | E8: IN셔틀 X1축 스캔 트리거 종료 위치 이동에 실패 했습니다 | F8: , | G8: IN_SHUTTLE_X1_AXIS_SCAN_TRIGGER_END_POSITION_MOVE_FAILED | H8: , | I8: IN_SHUTTLE_X1_AXIS_SCAN_TRIGGER_END_POSITION_MOVE_FAILED | J8: , | K8: IN_SHUTTLE trục X1 không thể di chuyển vị trí SCAN TRIGGER END | L8: , | M8: IN셔틀 X1축 드라이버 상태 확인해주세요. | N8: , | O8: CHECK THE DRIVER STATUS OF THE IN SHUTTLE X1 AXIS. | P8: , | Q8: CHECK THE DRIVER STATUS OF THE IN SHUTTLE X1 AXIS. | R8: , | S8: Hãy kiểm tra DRIVER trục X1 - IN SHUTTLE. | T8: , | U8: HEAVY | V8: , | W8: IN_SHUTTLE | X8: , | Y8: SQUARE | Z8: , | AA8: 0.0176565 | AB8: , | AC8: 0.453125 | AD8: , | AE8: 0.5184591 | AF8: , | AG8: 0.1315104 | AJ8: =VLOOKUP(Sheet1!W8,'알람 범위'!$D$2:$F$45,3,FALSE) -> 10500 | AK8: 4 | AL8: =AJ8+AK8 -> 10504 | AM8: =C8 -> MO_IN_SHUTTLE_X1_SCAN_TRIGGER_END_MOVE
A9: =AL9 -> 10505 | B9: , | C9: MO_IN_SHUTTLE_X1_ALIGN_MOVE | D9: , | E9: IN셔틀 X1축 얼라인 위치 이동에 실패 했습니다 | F9: , | G9: IN_SHUTTLE_X1_AXIS_ALIGN_POSITION_MOVE_FAILED | H9: , | I9: IN_SHUTTLE_X1_AXIS_ALIGN_POSITION_MOVE_FAILED | J9: , | K9: IN_SHUTTLE trục X1 không thể di chuyển vị trí ALIGN | L9: , | M9: IN셔틀 X1축 드라이버 상태 확인해주세요. | N9: , | O9: CHECK THE DRIVER STATUS OF THE IN SHUTTLE X1 AXIS. | P9: , | Q9: CHECK THE DRIVER STATUS OF THE IN SHUTTLE X1 AXIS. | R9: , | S9: Hãy kiểm tra DRIVER trục X1 - IN SHUTTLE. | T9: , | U9: HEAVY | V9: , | W9: IN_SHUTTLE | X9: , | Y9: SQUARE | Z9: , | AA9: 0.0176565 | AB9: , | AC9: 0.453125 | AD9: , | AE9: 0.5184591 | AF9: , | AG9: 0.1315104 | AJ9: =VLOOKUP(Sheet1!W9,'알람 범위'!$D$2:$F$45,3,FALSE) -> 10500 | AK9: 5 | AL9: =AJ9+AK9 -> 10505 | AM9: =C9 -> MO_IN_SHUTTLE_X1_ALIGN_MOVE
A10: =AL10 -> 10506 | B10: , | C10: MO_IN_SHUTTLE_X1_UNLOAD_MOVE | D10: , | E10: IN셔틀 X1축 언로드 위치 이동에 실패 했습니다 (IN로봇 위치) | F10: , | G10: IN_SHUTTLE_X1_AXIS_UNLOAD_POSITION_MOVE_FAILED (IN-ROBOT POSITION) | H10: , | I10: IN_SHUTTLE_X1_AXIS_UNLOAD_POSITION_MOVE_FAILED (IN-ROBOT POSITION) | J10: , | K10: IN_SHUTTLE trục X1 không thể di chuyển vị trí UNLOAD (IN-ROBOT POSITION) | L10: , | M10: IN셔틀 X1축 드라이버 상태 확인해주세요. | N10: , | O10: CHECK THE DRIVER STATUS OF THE IN SHUTTLE X1 AXIS. | P10: , | Q10: CHECK THE DRIVER STATUS OF THE IN SHUTTLE X1 AXIS. | R10: , | S10: Hãy kiểm tra DRIVER trục X1 - IN SHUTTLE. | T10: , | U10: HEAVY | V10: , | W10: IN_SHUTTLE | X10: , | Y10: SQUARE | Z10: , | AA10: 0.0176565 | AB10: , | AC10: 0.453125 | AD10: , | AE10: 0.5184591 | AF10: , | AG10: 0.1315104 | AJ10: =VLOOKUP(Sheet1!W10,'알람 범위'!$D$2:$F$45,3,FALSE) -> 10500 | AK10: 6 | AL10: =AJ10+AK10 -> 10506 | AM10: =C10 -> MO_IN_SHUTTLE_X1_UNLOAD_MOVE
A11: =AL11 -> 10600 | B11: , | C11: VC_IN_SHUTTLE_P1_VACUUM | D11: , | E11: IN셔틀 P1 진공 흡착에 실패 했습니다 | F11: , | G11: IN_SHUTTLE_P1_VACUUM_FAILED | H11: , | I11: IN_SHUTTLE_P1_VACUUM_FAILED | J11: , | K11: IN_SHUTTLE_P1_VACUUM_FAILED | L11: , | M11: IN셔틀 P1 진공 상태를 확인해주세요. | N11: , | O11: CHECK THE VACUUM STATUS OF THE IN SHUTTLE P1. | P11: , | Q11: CHECK THE VACUUM STATUS OF THE IN SHUTTLE P1. | R11: , | S11: CHECK THE VACUUM STATUS OF THE IN SHUTTLE P1. | T11: , | U11: HEAVY | V11: , | W11: IN_SHUTTLE | X11: , | Y11: SQUARE | Z11: , | AA11: 0.1284109 | AB11: , | AC11: 0.4505208 | AD11: , | AE11: 0.09149278 | AF11: , | AG11: 0.1132813 | AJ11: =VLOOKUP(Sheet1!W11,'알람 범위'!$D$2:$F$45,3,FALSE) -> 10500 | AK11: 100 | AL11: =AJ11+AK11 -> 10600 | AM11: =C11 -> VC_IN_SHUTTLE_P1_VACUUM
A12: =AL12 -> 10601 | B12: , | C12: VC_IN_SHUTTLE_P1_BLOW | D12: , | E12: IN셔틀 P1 진공 파기에 실패 했습니다 | F12: , | G12: IN_SHUTTLE_P1_BLOW_FAILED | H12: , | I12: IN_SHUTTLE_P1_BLOW_FAILED | J12: , | K12: IN_SHUTTLE_P1_BLOW_FAILED | L12: , | M12: IN셔틀 P1 진공 상태를 확인해주세요. | N12: , | O12: CHECK THE VACUUM STATUS OF THE IN SHUTTLE P1. | P12: , | Q12: CHECK THE VACUUM STATUS OF THE IN SHUTTLE P1. | R12: , | S12: CHECK THE VACUUM STATUS OF THE IN SHUTTLE P1. | T12: , | U12: HEAVY | V12: , | W12: IN_SHUTTLE | X12: , | Y12: SQUARE | Z12: , | AA12: 0.1284109 | AB12: , | AC12: 0.4505208 | AD12: , | AE12: 0.09149278 | AF12: , | AG12: 0.1132813 | AJ12: =VLOOKUP(Sheet1!W12,'알람 범위'!$D$2:$F$45,3,FALSE) -> 10500 | AK12: 101 | AL12: =AJ12+AK12 -> 10601 | AM12: =C12 -> VC_IN_SHUTTLE_P1_BLOW
A13: =AL13 -> 10602 | B13: , | C13: SE_IN_SHUTTLE_P1_VACUUM_CHECK | D13: , | E13: IN셔틀 P1 셀 확인에 실패 했습니다 (진공) | F13: , | G13: IN_SHUTTLE_P1_CELL_VACUUM_CHECK_FAILED | H13: , | I13: IN_SHUTTLE_P1_CELL_VACUUM_CHECK_FAILED | J13: , | K13: IN_SHUTTLE_P1_CELL_VACUUM_CHECK_FAILED | L13: , | M13: IN셔틀 P1 진공 상태를 확인해주세요. | N13: , | O13: CHECK THE VACUUM STATUS OF THE IN SHUTTLE P1. | P13: , | Q13: CHECK THE VACUUM STATUS OF THE IN SHUTTLE P1. | R13: , | S13: CHECK THE VACUUM STATUS OF THE IN SHUTTLE P1. | T13: , | U13: HEAVY | V13: , | W13: IN_SHUTTLE | X13: , | Y13: SQUARE | Z13: , | AA13: 0.1284109 | AB13: , | AC13: 0.4505208 | AD13: , | AE13: 0.09149278 | AF13: , | AG13: 0.1132813 | AJ13: =VLOOKUP(Sheet1!W13,'알람 범위'!$D$2:$F$45,3,FALSE) -> 10500 | AK13: 102 | AL13: =AJ13+AK13 -> 10602 | AM13: =C13 -> SE_IN_SHUTTLE_P1_VACUUM_CHECK
... A194: =AL194 -> 29999 | B194: , | C194: CO_TRANSFER_CIM_N_CIM_DISCONNECTED | D194: , | E194: CIM 통신 연결이 끊겼습니다 | F194: , | G194: CIM_IS_DISCONNECTED | H194: , | I194: CIM_IS_DISCONNECTED | J194: , | K194: CIM_IS_DISCONNECTED | L194: , | M194: CIM 연결 상태를 확인해주세요. | N194: , | O194: CHECK THE CIM CONNECTION STATUS. | P194: , | Q194: CHECK THE CIM CONNECTION STATUS. | R194: , | S194: CHECK THE CIM CONNECTION STATUS. | T194: , | U194: HEAVY | V194: , | W194: CIM | X194: , | Y194: SQUARE | Z194: , | AA194: 0 | AB194: , | AC194: 0 | AD194: , | AE194: 0 | AF194: , | AG194: 0 | AJ194: =VLOOKUP(Sheet1!W194,'알람 범위'!$D$2:$F$45,3,FALSE) -> 29500 | AK194: 499 | AL194: =AJ194+AK194 -> 29999 | AM194: =C194 -> CO_TRANSFER_CIM_N_CIM_DISCONNECTED
A195: =AL195 -> 30000 | B195: , | C195: UT_MAIN_ELECTRONICBOX_TEMPERATURE_1_N_OVER40 | D195: , | E195: 전장반 온도가 40도를 초과 했습니다 | F195: =D195 -> , | G195: ELECTRONIC_BOX_OVER_40_TEMPERATURE_DEGREE | H195: =D195 -> , | I195: ELECTRONIC_BOX_OVER_40_TEMPERATURE_DEGREE | J195: =F195 -> , | K195: ELECTRONIC_BOX_OVER_40_TEMPERATURE_DEGREE | L195: =H195 -> , | M195: 설비 온도를 확인하고 리셋 버튼을 눌러 클리어 해주세요. | N195: =J195 -> , | O195: Check the equipment temperature sensor and press the reset button to clear it. | P195: =L195 -> , | Q195: Check the equipment temperature sensor and press the reset button to clear it. | R195: =N195 -> , | S195: Check the equipment temperature sensor and press the reset button to clear it. | T195: =P195 -> , | U195: HEAVY | V195: =R195 -> , | W195: SAFETY | X195: , | Y195: SQUARE | Z195: , | AA195: 0.1974318 | AB195: , | AC195: 0.02083333 | AD195: , | AE195: 0.788122 | AF195: , | AG195: 0.2096354 | AJ195: =VLOOKUP(Sheet1!W195,'알람 범위'!$D$2:$F$45,3,FALSE) -> 30000 | AK195: 0 | AL195: =AJ195+AK195 -> 30000 | AM195: =C195 -> UT_MAIN_ELECTRONICBOX_TEMPERATURE_1_N_OVER40
A196: =AL196 -> 30001 | B196: , | C196: UT_MAIN_PCRACK_TEMPERATURE_1_N_OVER40 | D196: , | E196: PC 랙 온도가 40도를 초과 했습니다 | F196: =D196 -> , | G196: PC_RACK_OVER_40_TEMPERATURE_DEGREE | H196: =D196 -> , | I196: PC_RACK_OVER_40_TEMPERATURE_DEGREE | J196: =F196 -> , | K196: PC_RACK_OVER_40_TEMPERATURE_DEGREE | L196: =H196 -> , | M196: 설비 온도를 확인하고 리셋 버튼을 눌러 클리어 해주세요. | N196: =J196 -> , | O196: Check the equipment temperature sensor and press the reset button to clear it. | P196: =L196 -> , | Q196: Check the equipment temperature sensor and press the reset button to clear it. | R196: =N196 -> , | S196: Check the equipment temperature sensor and press the reset button to clear it. | T196: =P196 -> , | U196: HEAVY | V196: =R196 -> , | W196: SAFETY | X196: , | Y196: SQUARE | Z196: , | AA196: 0.4863563 | AB196: , | AC196: 0.7460938 | AD196: , | AE196: 0.2375602 | AF196: , | AG196: 0.2526042 | AJ196: =VLOOKUP(Sheet1!W196,'알람 범위'!$D$2:$F$45,3,FALSE) -> 30000 | AK196: 1 | AL196: =AJ196+AK196 -> 30001 | AM196: =C196 -> UT_MAIN_PCRACK_TEMPERATURE_1_N_OVER40
A197: =AL197 -> 30002 | B197: , | C197: UT_MAIN_ELECTRONICBOX_SMOKE_SENSOR_1_N_DETECTED | D197: , | E197: 전장반에 연기가 감지되었습니다 | F197: , | G197: ELECTRONIC_BOX_SMOKE_SENSOR_ALARM | H197: , | I197: ELECTRONIC_BOX_SMOKE_SENSOR_ALARM | J197: , | K197: ELECTRONIC_BOX_SMOKE_SENSOR_ALARM | L197: , | M197: 전장반에 연기를 확인해주세요. | N197: , | O197: Smoke Sensor Detect & Check | P197: , | Q197: Smoke Sensor Detect & Check | R197: , | S197: Smoke Sensor Detect & Check | T197: , | U197: HEAVY | V197: , | W197: SAFETY | X197: , | Y197: SQUARE | Z197: , | AA197: 0.1974318 | AB197: , | AC197: 0.02083333 | AD197: , | AE197: 0.788122 | AF197: , | AG197: 0.2096354 | AJ197: =VLOOKUP(Sheet1!W197,'알람 범위'!$D$2:$F$45,3,FALSE) -> 30000 | AK197: 2 | AL197: =AJ197+AK197 -> 30002 | AM197: =C197 -> UT_MAIN_ELECTRONICBOX_SMOKE_SENSOR_1_N_DETECTED
A198: =AL198 -> 30003 | B198: , | C198: UT_MAIN_SAFETYPLC_GPS_MC_POWER_OFF | D198: , | E198: 세이프티 PLC 문제 발생하여 설비 MAGNET 전원이 OFF 되었습니다 | F198: , | G198: EQUIPMENT_GPS_MC_POWER_OFF | H198: , | I198: EQUIPMENT_GPS_MC_POWER_OFF | J198: , | K198: Do SAFETY PLC phát sinh vấn đề nên nguồn điện thiết bị MAGNET đã bị OFF | L198: , | M198: 비상 정지 버튼 상태를 확인해주세요. | N198: , | O198: PLC Signal Nomal IO Check | P198: , | Q198: PLC Signal Nomal IO Check | R198: , | S198: Hãy kiểm tra tình trạng nút dừng khẩn cấp | T198: , | U198: HEAVY | V198: , | W198: SAFETY | X198: , | Y198: SQUARE | Z198: , | AA198: 0 | AB198: , | AC198: 0 | AD198: , | AE198: 0 | AF198: , | AG198: 0 | AJ198: =VLOOKUP(Sheet1!W198,'알람 범위'!$D$2:$F$45,3,FALSE) -> 30000 | AK198: 3 | AL198: =AJ198+AK198 -> 30003 | AM198: =C198 -> UT_MAIN_SAFETYPLC_GPS_MC_POWER_OFF
A199: =AL199 -> 30004 | B199: , | C199: CO_MAIN_DEVICE_MCU_DISCONNECTED | D199: , | E199: FFU컨트롤러 연결이 끊어졌습니다. | F199: , | G199: MCU_IS_DISCONNECTED | H199: , | I199: MCU_IS_DISCONNECTED | J199: , | K199: MCU_IS_DISCONNECTED | L199: , | M199: 설비 FFU컨트롤러를 확인해주세요. | N199: , | O199: Check the equipment MCU. | P199: , | Q199: Check the equipment MCU. | R199: , | S199: Check the equipment MCU. | T199: , | U199: HEAVY | V199: , | W199: SAFETY | X199: , | Y199: SQUARE | Z199: , | AA199: 0.1813804 | AB199: , | AC199: 0.9205729 | AD199: , | AE199: 0.8073837 | AF199: , | AG199: 0.07291666 | AJ199: =VLOOKUP(Sheet1!W199,'알람 범위'!$D$2:$F$45,3,FALSE) -> 30000 | AK199: 4 | AL199: =AJ199+AK199 -> 30004 | AM199: =C199 -> CO_MAIN_DEVICE_MCU_DISCONNECTED
A200: =AL200 -> 30005 | B200: , | C200: CO_MAIN_DEVICE_GMS_DISCONNECTED | D200: , | E200: 접지 저항 측정기 연결이 끊어졌습니다. | F200: , | G200: GMS_IS_DISCONNECTED | H200: , | I200: GMS_IS_DISCONNECTED | J200: , | K200: GMS_IS_DISCONNECTED | L200: , | M200: 설비 접지 저항 측정기를 확인해주세요. | N200: , | O200: Check the equipment GMS. | P200: , | Q200: Check the equipment GMS. | R200: , | S200: Check the equipment GMS. | T200: , | U200: HEAVY | V200: , | W200: SAFETY | X200: , | Y200: SQUARE | Z200: , | AA200: 0 | AB200: , | AC200: 0 | AD200: , | AE200: 0 | AF200: , | AG200: 0 | AJ200: =VLOOKUP(Sheet1!W200,'알람 범위'!$D$2:$F$45,3,FALSE) -> 30000 | AK200: 5 | AL200: =AJ200+AK200 -> 30005 | AM200: =C200 -> CO_MAIN_DEVICE_GMS_DISCONNECTED
A201: =AL201 -> 30006 | B201: , | C201: CO_MAIN_ELECTRONICBOX_TEMPERATURE_DISCONNECTED | D201: , | E201: 전장반 온도컨트롤러 연결이 끊어졌습니다. | F201: , | G201: ELECTRONICBOX_TEMPERATURE_DISCONNECTED | H201: , | I201: ELECTRONICBOX_TEMPERATURE_DISCONNECTED | J201: , | K201: ELECTRONICBOX_TEMPERATURE_DISCONNECTED | L201: , | M201: 설비 온도컨트롤러를 확인해주세요. | N201: , | O201: Check the equipment main temperature sensor. | P201: , | Q201: Check the equipment main temperature sensor. | R201: , | S201: Check the equipment main temperature sensor. | T201: , | U201: HEAVY | V201: , | W201: SAFETY | X201: , | Y201: SQUARE | Z201: , | AA201: 0.1974318 | AB201: , | AC201: 0.02083333 | AD201: , | AE201: 0.788122 | AF201: , | AG201: 0.2096354 | AJ201: =VLOOKUP(Sheet1!W201,'알람 범위'!$D$2:$F$45,3,FALSE) -> 30000 | AK201: 6 | AL201: =AJ201+AK201 -> 30006 | AM201: =C201 -> CO_MAIN_ELECTRONICBOX_TEMPERATURE_DISCONNECTED
A202: =AL202 -> 30007 | B202: , | C202: CO_MAIN_PCRACK_TEMPERATURE_DISCONNECTED | D202: , | E202: PC 랙 온도컨트롤러 연결이 끊어졌습니다. | F202: , | G202: PCRACK_TEMPERATURE_DISCONNECTED | H202: , | I202: PCRACK_TEMPERATURE_DISCONNECTED | J202: , | K202: PCRACK_TEMPERATURE_DISCONNECTED | L202: , | M202: 설비 온도컨트롤러를 확인해주세요. | N202: , | O202: Check the equipment main temperature sensor. | P202: , | Q202: Check the equipment main temperature sensor. | R202: , | S202: Check the equipment main temperature sensor. | T202: , | U202: HEAVY | V202: , | W202: SAFETY | X202: , | Y202: SQUARE | Z202: , | AA202: 0.4863563 | AB202: , | AC202: 0.7460938 | AD202: , | AE202: 0.2375602 | AF202: , | AG202: 0.2526042 | AJ202: =VLOOKUP(Sheet1!W202,'알람 범위'!$D$2:$F$45,3,FALSE) -> 30000 | AK202: 7 | AL202: =AJ202+AK202 -> 30007 | AM202: =C202 -> CO_MAIN_PCRACK_TEMPERATURE_DISCONNECTED
A203: =AL203 -> 30008 | B203: , | C203: OP_MAIN_MODEKEY_N_TEACH | D203: , | E203: 설비 구동중에 세이프티키가 TEACH로 변경되었습니다 | F203: , | G203: SAFTTY_KEY_IS_NOT_AUTO | H203: , | I203: SAFTTY_KEY_IS_NOT_AUTO | J203: , | K203: Trong khi chuyển động SAFTTY_KEY đã chuyển sang TEACH | L203: , | M203: 설비 세이프티 키를 오토로 변경 해주십시오. | N203: , | O203: Safty Key turn AUTO | P203: , | Q203: Safty Key turn AUTO | R203: , | S203: Hãy chuyển Safty Key về chế độ tự động ( AUTO ) | T203: , | U203: HEAVY | V203: , | W203: SAFETY | X203: , | Y203: SQUARE | Z203: , | AA203: 0 | AB203: , | AC203: 0 | AD203: , | AE203: 0 | AF203: , | AG203: 0 | AJ203: =VLOOKUP(Sheet1!W203,'알람 범위'!$D$2:$F$45,3,FALSE) -> 30000 | AK203: 8 | AL203: =AJ203+AK203 -> 30008 | AM203: =C203 -> OP_MAIN_MODEKEY_N_TEACH
A204: =AL204 -> 30009 | B204: , | C204: OP_MAIN_UNIT_ALL_STOP | D204: , | E204: 설비에 모든 유닛이 정지 상태입니다 | F204: , | G204: ALL_UNITS_IN_THE_EQUIPMENT_WAS_STOPPED | H204: , | I204: ALL_UNITS_IN_THE_EQUIPMENT_WAS_STOPPED | J204: , | K204: ALL_UNITS_IN_THE_EQUIPMENT_WAS_STOPPED | L204: , | M204: 설비에 유닛을 사용 상태로 변경해 주십시오. | N204: , | O204: Please change the unit to active in the equipment. | P204: , | Q204: Please change the unit to active in the equipment. | R204: , | S204: Please change the unit to active in the equipment. | T204: , | U204: HEAVY | V204: , | W204: SAFETY | X204: , | Y204: SQUARE | Z204: , | AA204: 0 | AB204: , | AC204: 0 | AD204: , | AE204: 0 | AF204: , | AG204: 0 | AJ204: =VLOOKUP(Sheet1!W204,'알람 범위'!$D$2:$F$45,3,FALSE) -> 30000 | AK204: 9 | AL204: =AJ204+AK204 -> 30009 | AM204: =C204 -> OP_MAIN_UNIT_ALL_STOP
A205: =AL205 -> 30010 | B205: , | C205: VC_MAIN_VACUUM_MAIN_SUPPLY | D205: , | E205: 메인 진공 공압이 설정 값보다 낮아졌습니다 | F205: , | G205: MAIN_VAC_PRESSURE_SENSOR_ALARM | H205: , | I205: MAIN_VAC_PRESSURE_SENSOR_ALARM | J205: , | K205: Áp suất khí nén chân không chính ( MAIN_VAC ) thấp hơn giá trị đặt. | L205: , | M205: 메인 진공 공압 값을 확인해주세요. | N205: , | O205: Main Vacuum Pressure Sensor or Main Vacuum Check | P205: , | Q205: Main Vacuum Pressure Sensor or Main Vacuum Check | R205: , | S205: Hãy kiểm tra giá trị khí nén chân không chính ( Main Vacuum Pressure Sensor or Main Vacuum ) | T205: , | U205: HEAVY | V205: , | W205: SAFETY | X205: , | Y205: SQUARE | Z205: , | AA205: 0 | AB205: , | AC205: 0 | AD205: , | AE205: 0 | AF205: , | AG205: 0 | AJ205: =VLOOKUP(Sheet1!W205,'알람 범위'!$D$2:$F$45,3,FALSE) -> 30000 | AK205: 10 | AL205: =AJ205+AK205 -> 30010 | AM205: =C205 -> VC_MAIN_VACUUM_MAIN_SUPPLY
A206: =AL206 -> 30011 | B206: , | C206: VC_INSP_STAGE_VACUUM_MAIN_SUPPLY | D206: , | E206: 검사스테이지 메인 진공 공압이 설정 값보다 낮아졌습니다 | F206: , | G206: INSP_STAGE_MAIN_VAC_PRESSURE_SENSOR_ALARM | H206: , | I206: INSP_STAGE_MAIN_VAC_PRESSURE_SENSOR_ALARM | J206: , | K206: Áp suất khí nén chân không chính ( INSP_STAGE_VAC ) thấp hơn giá trị đặt. | L206: , | M206: 검사스테이지 메인 진공 공압 값을 확인해주세요. | N206: , | O206: Inspection Stage Main Vacuum Pressure Sensor or Main Vacuum Check | P206: , | Q206: Inspection Stage Main Vacuum Pressure Sensor or Main Vacuum Check | R206: , | S206: Hãy kiểm tra giá trị khí nén chân không chính ( Inspection Stage Main Vacuum Pressure Sensor or Main Vacuum ) | T206: , | U206: HEAVY | V206: , | W206: SAFETY | X206: , | Y206: SQUARE | Z206: , | AA206: 0 | AB206: , | AC206: 0 | AD206: , | AE206: 0 | AF206: , | AG206: 0 | AJ206: =VLOOKUP(Sheet1!W206,'알람 범위'!$D$2:$F$45,3,FALSE) -> 30000 | AK206: 11 | AL206: =AJ206+AK206 -> 30011 | AM206: =C206 -> VC_INSP_STAGE_VACUUM_MAIN_SUPPLY
A207: =AL207 -> 30012 | B207: , | C207: VC_MAIN_AIR_MAIN_N_SUPPLY | D207: , | E207: 메인 공압이 설정 값보다 낮아졌습니다 | F207: , | G207: MAIN_AIR_PRESSURE_SENSOR_ALARM | H207: , | I207: MAIN_AIR_PRESSURE_SENSOR_ALARM | J207: , | K207: Áp suất khí nén chính ( MAIN_AIR ) thấp hơn giá trị đặt. | L207: , | M207: 메인 공압 값을 확인해주세요. | N207: , | O207: Main Air Pressure Sensor or Main Air Check | P207: , | Q207: Main Air Pressure Sensor or Main Air Check | R207: , | S207: Hãy kiểm tra giá trị khí nén chính ( Main Air Pressure Sensor or Main Air ) | T207: , | U207: HEAVY | V207: , | W207: SAFETY | X207: , | Y207: SQUARE | Z207: , | AA207: 0 | AB207: , | AC207: 0 | AD207: , | AE207: 0 | AF207: , | AG207: 0 | AJ207: =VLOOKUP(Sheet1!W207,'알람 범위'!$D$2:$F$45,3,FALSE) -> 30000 | AK207: 12 | AL207: =AJ207+AK207 -> 30012 | AM207: =C207 -> VC_MAIN_AIR_MAIN_N_SUPPLY
A208: =AL208 -> 30013 | B208: , | C208: UT_MAIN_ELECTRONICBOX_FAN_1_STOP | D208: , | E208: MAIN 전장반 FAN1이 정지했습니다 | F208: =D208 -> , | G208: SAFETY_MAIN_ELECTRONICBOX_FAN_1_STOP_ALARM | H208: =D208 -> , | I208: SAFETY_MAIN_ELECTRONICBOX_FAN_1_STOP_ALARM | J208: =F208 -> , | K208: MAIN_ELECTRONICBOX_FAN_1 đã dừng | L208: =H208 -> , | M208: 전장반에 팬1을 확인해주세요. | N208: , | O208: Main Electronic Box FAN1 Check | P208: , | Q208: Main Electronic Box FAN1 Check | R208: , | S208: Hãy kiểm tra Main Electronic Box FAN1 | T208: =P208 -> , | U208: LIGHT | V208: =R208 -> , | W208: SAFETY | X208: , | Y208: SQUARE | Z208: , | AA208: 0.200642 | AB208: , | AC208: 0.02083333 | AD208: , | AE208: 0.7817014 | AF208: , | AG208: 0.04817708 | AJ208: =VLOOKUP(Sheet1!W208,'알람 범위'!$D$2:$F$45,3,FALSE) -> 30000 | AK208: 13 | AL208: =AJ208+AK208 -> 30013 | AM208: =C208 -> UT_MAIN_ELECTRONICBOX_FAN_1_STOP
A209: =AL209 -> 30014 | B209: , | C209: UT_MAIN_ELECTRONICBOX_FAN_2_STOP | D209: , | E209: MAIN 전장반 FAN2가 정지했습니다 | F209: =D209 -> , | G209: SAFETY_MAIN_ELECTRONICBOX_FAN_2_STOP_ALARM | H209: =D209 -> , | I209: SAFETY_MAIN_ELECTRONICBOX_FAN_2_STOP_ALARM | J209: =F209 -> , | K209: MAIN_ELECTRONICBOX_FAN_2 đã dừng | L209: =H209 -> , | M209: 전장반에 팬2를 확인해주세요. | N209: , | O209: Main Electronic Box FAN2 Check | P209: , | Q209: Main Electronic Box FAN2 Check | R209: , | S209: Hãy kiểm tra Main Electronic Box FAN2 | T209: =P209 -> , | U209: LIGHT | V209: =R209 -> , | W209: SAFETY | X209: , | Y209: SQUARE | Z209: , | AA209: 0.200642 | AB209: , | AC209: 0.02083333 | AD209: , | AE209: 0.7817014 | AF209: , | AG209: 0.04817708 | AJ209: =VLOOKUP(Sheet1!W209,'알람 범위'!$D$2:$F$45,3,FALSE) -> 30000 | AK209: 14 | AL209: =AJ209+AK209 -> 30014 | AM209: =C209 -> UT_MAIN_ELECTRONICBOX_FAN_2_STOP
A210: =AL210 -> 30015 | B210: , | C210: UT_MAIN_MCU_FFU_1_STOP | D210: , | E210: MAIN MCU 그룹에 FFU#1에 FAN이 정지했습니다 | F210: , | G210: MAIN_MCU_GROUP_FFU_1_STOP_ALARM | H210: , | I210: MAIN_MCU_GROUP_FFU_1_STOP_ALARM | J210: , | K210: MAIN_MCU_GROUP_FFU_1_STOP_ALARM | L210: , | M210: MAIN MCU를 확인해주세요. | N210: , | O210: Check the main MCU. | P210: , | Q210: Check the main MCU. | R210: , | S210: Check the main MCU. | T210: , | U210: LIGHT | V210: , | W210: SAFETY | X210: , | Y210: SQUARE | Z210: , | AA210: 0.3515249 | AB210: , | AC210: 0.3658854 | AD210: , | AE210: 0.5168539 | AF210: , | AG210: 0.2604167 | AJ210: =VLOOKUP(Sheet1!W210,'알람 범위'!$D$2:$F$45,3,FALSE) -> 30000 | AK210: 15 | AL210: =AJ210+AK210 -> 30015 | AM210: =C210 -> UT_MAIN_MCU_FFU_1_STOP
A211: =AL211 -> 30016 | B211: , | C211: UT_MAIN_MCU_FFU_1_ALARM_OCCURRED | D211: , | E211: MAIN MCU 그룹에 FFU#1에 FAN에 알람이 발생했습니다 | F211: , | G211: MAIN_MCU_GROUP_FFU_1_ALARM_OCCURRED | H211: , | I211: MAIN_MCU_GROUP_FFU_1_ALARM_OCCURRED | J211: , | K211: MAIN_MCU_GROUP_FFU_1_ALARM_OCCURRED | L211: , | M211: MAIN MCU를 확인해주세요. | N211: , | O211: Check the main MCU. | P211: , | Q211: Check the main MCU. | R211: , | S211: Check the main MCU. | T211: , | U211: LIGHT | V211: , | W211: SAFETY | X211: , | Y211: SQUARE | Z211: , | AA211: 0.3515249 | AB211: , | AC211: 0.3658854 | AD211: , | AE211: 0.5168539 | AF211: , | AG211: 0.2604167 | AJ211: =VLOOKUP(Sheet1!W211,'알람 범위'!$D$2:$F$45,3,FALSE) -> 30000 | AK211: 16 | AL211: =AJ211+AK211 -> 30016 | AM211: =C211 -> UT_MAIN_MCU_FFU_1_ALARM_OCCURRED
A212: =AL212 -> 30100 | B212: , | C212: EM_MAIN_CONTROLPANEL_FRONT_EMS_X000 | D212: , | E212: 정면 비상 정지 버튼#1이 눌렸습니다 | F212: =D212 -> , | G212: EQUIPMENT_FRONT_EMERGENCY_SWITCH_1_PUSH | H212: =D212 -> , | I212: EQUIPMENT_FRONT_EMERGENCY_SWITCH_1_PUSH | J212: =F212 -> , | K212: EQUIPMENT_FRONT_EMERGENCY_SWITCH_1_PUSH | L212: =H212 -> , | M212: 비상 정지 버튼 상태를 확인해주세요. | N212: =J212 -> , | O212: CHECK EMERGENCY BUTTON STATUS. | P212: =L212 -> , | Q212: CHECK EMERGENCY BUTTON STATUS. | R212: =N212 -> , | S212: Hãy kiểm tra tình trạng nút dừng khẩn cấp | T212: =P212 -> , | U212: HEAVY | V212: =R212 -> , | W212: SAFETY | X212: , | Y212: SQUARE | Z212: , | AA212: 0.6966292 | AB212: , | AC212: 0.9010417 | AD212: , | AE212: 0.2520064 | AF212: , | AG212: 0.08984375 | AJ212: =VLOOKUP(Sheet1!W212,'알람 범위'!$D$2:$F$45,3,FALSE) -> 30000 | AK212: 100 | AL212: =AJ212+AK212 -> 30100 | AM212: =C212 -> EM_MAIN_CONTROLPANEL_FRONT_EMS_X000
A213: =AL213 -> 30101 | B213: , | C213: EM_MAIN_CONTROLPANEL_REAR_EMS_X001 | D213: , | E213: 후면 비상 정지 버튼#2이 눌렸습니다 | F213: =D213 -> , | G213: EQUIPMENT_REAR_EMERGENCY_SWITCH_2_PUSH | H213: =D213 -> , | I213: EQUIPMENT_REAR_EMERGENCY_SWITCH_2_PUSH | J213: =F213 -> , | K213: EQUIPMENT_REAR_EMERGENCY_SWITCH_2_PUSH | L213: =H213 -> , | M213: 비상 정지 버튼 상태를 확인해주세요. | N213: =J213 -> , | O213: CHECK EMERGENCY BUTTON STATUS. | P213: =L213 -> , | Q213: CHECK EMERGENCY BUTTON STATUS. | R213: =N213 -> , | S213: Hãy kiểm tra tình trạng nút dừng khẩn cấp | T213: =P213 -> , | U213: HEAVY | V213: =R213 -> , | W213: SAFETY | X213: , | Y213: SQUARE | Z213: , | AA213: 0.1958266 | AB213: , | AC213: 0.009114583 | AD213: , | AE213: 0.2616372 | AF213: , | AG213: 0.09635416 | AJ213: =VLOOKUP(Sheet1!W213,'알람 범위'!$D$2:$F$45,3,FALSE) -> 30000 | AK213: 101 | AL213: =AJ213+AK213 -> 30101 | AM213: =C213 -> EM_MAIN_CONTROLPANEL_REAR_EMS_X001
A214: =AL214 -> 30102 | B214: , | C214: EM_TRANSFER_ROBOT_IN_PENDANT_EMS | D214: , | E214: IN로봇 팬던트에 비상 정지 버튼이 눌렸습니다 | F214: =D214 -> , | G214: IN_ROBOT_PENDANT_EMERGENCY_SWITCH_PUSH | H214: =D214 -> , | I214: IN_ROBOT_PENDANT_EMERGENCY_SWITCH_PUSH | J214: =F214 -> , | K214: IN_ROBOT_PENDANT_EMERGENCY_SWITCH_PUSH | L214: =H214 -> , | M214: 비상 정지 버튼 상태를 확인해주세요. | N214: =J214 -> , | O214: CHECK EMERGENCY BUTTON STATUS. | P214: =L214 -> , | Q214: CHECK EMERGENCY BUTTON STATUS. | R214: =N214 -> , | S214: Hãy kiểm tra tình trạng nút dừng khẩn cấp | T214: =P214 -> , | U214: HEAVY | V214: =R214 -> , | W214: SAFETY | X214: , | Y214: SQUARE | Z214: , | AA214: 0 | AB214: , | AC214: 0 | AD214: , | AE214: 0 | AF214: , | AG214: 0 | AJ214: =VLOOKUP(Sheet1!W214,'알람 범위'!$D$2:$F$45,3,FALSE) -> 30000 | AK214: 102 | AL214: =AJ214+AK214 -> 30102 | AM214: =C214 -> EM_TRANSFER_ROBOT_IN_PENDANT_EMS
A215: =AL215 -> 30103 | B215: , | C215: EM_TRANSFER_ROBOT_IN_CONTROLLER_EMS | D215: , | E215: IN로봇 컨트롤러에 비상 정지 버튼이 눌렸습니다 | F215: =D215 -> , | G215: IN_ROBOT_CONTROLLER_EMERGENCY_SWITCH_PUSH | H215: =D215 -> , | I215: IN_ROBOT_CONTROLLER_EMERGENCY_SWITCH_PUSH | J215: =F215 -> , | K215: IN_ROBOT_CONTROLLER_EMERGENCY_SWITCH_PUSH | L215: =H215 -> , | M215: 비상 정지 버튼 상태를 확인해주세요. | N215: =J215 -> , | O215: CHECK EMERGENCY BUTTON STATUS. | P215: =L215 -> , | Q215: CHECK EMERGENCY BUTTON STATUS. | R215: =N215 -> , | S215: Hãy kiểm tra tình trạng nút dừng khẩn cấp | T215: =P215 -> , | U215: HEAVY | V215: =R215 -> , | W215: SAFETY | X215: , | Y215: SQUARE | Z215: , | AA215: 0 | AB215: , | AC215: 0 | AD215: , | AE215: 0 | AF215: , | AG215: 0 | AJ215: =VLOOKUP(Sheet1!W215,'알람 범위'!$D$2:$F$45,3,FALSE) -> 30000 | AK215: 103 | AL215: =AJ215+AK215 -> 30103 | AM215: =C215 -> EM_TRANSFER_ROBOT_IN_CONTROLLER_EMS
A216: =AL216 -> 30104 | B216: , | C216: EM_TRANSFER_ROBOT_OUT_PENDANT_EMS | D216: , | E216: OUT로봇 팬던트에 비상 정지 버튼이 눌렸습니다 | F216: =D216 -> , | G216: OUT_ROBOT_PENDANT_EMERGENCY_SWITCH_PUSH | H216: =D216 -> , | I216: OUT_ROBOT_PENDANT_EMERGENCY_SWITCH_PUSH | J216: =F216 -> , | K216: OUT_ROBOT_PENDANT_EMERGENCY_SWITCH_PUSH | L216: =H216 -> , | M216: 비상 정지 버튼 상태를 확인해주세요. | N216: =J216 -> , | O216: CHECK EMERGENCY BUTTON STATUS. | P216: =L216 -> , | Q216: CHECK EMERGENCY BUTTON STATUS. | R216: =N216 -> , | S216: Hãy kiểm tra tình trạng nút dừng khẩn cấp | T216: =P216 -> , | U216: HEAVY | V216: =R216 -> , | W216: SAFETY | X216: , | Y216: SQUARE | Z216: , | AA216: 0 | AB216: , | AC216: 0 | AD216: , | AE216: 0 | AF216: , | AG216: 0 | AJ216: =VLOOKUP(Sheet1!W216,'알람 범위'!$D$2:$F$45,3,FALSE) -> 30000 | AK216: 104 | AL216: =AJ216+AK216 -> 30104 | AM216: =C216 -> EM_TRANSFER_ROBOT_OUT_PENDANT_EMS
A217: =AL217 -> 30105 | B217: , | C217: EM_TRANSFER_ROBOT_OUT_CONTROLLER_EMS | D217: , | E217: OUT로봇 컨트롤러에 비상 정지 버튼이 눌렸습니다 | F217: =D217 -> , | G217: OUT_ROBOT_CONTROLLER_EMERGENCY_SWITCH_PUSH | H217: =D217 -> , | I217: OUT_ROBOT_CONTROLLER_EMERGENCY_SWITCH_PUSH | J217: =F217 -> , | K217: OUT_ROBOT_CONTROLLER_EMERGENCY_SWITCH_PUSH | L217: =H217 -> , | M217: 비상 정지 버튼 상태를 확인해주세요. | N217: =J217 -> , | O217: CHECK EMERGENCY BUTTON STATUS. | P217: =L217 -> , | Q217: CHECK EMERGENCY BUTTON STATUS. | R217: =N217 -> , | S217: Hãy kiểm tra tình trạng nút dừng khẩn cấp | T217: =P217 -> , | U217: HEAVY | V217: =R217 -> , | W217: SAFETY | X217: , | Y217: SQUARE | Z217: , | AA217: 0 | AB217: , | AC217: 0 | AD217: , | AE217: 0 | AF217: , | AG217: 0 | AJ217: =VLOOKUP(Sheet1!W217,'알람 범위'!$D$2:$F$45,3,FALSE) -> 30000 | AK217: 105 | AL217: =AJ217+AK217 -> 30105 | AM217: =C217 -> EM_TRANSFER_ROBOT_OUT_CONTROLLER_EMS
A218: =AL218 -> 30106 | B218: , | C218: DO_MAIN_ANY_DOOR_FORECE_RELEASED_X02A | D218: , | E218: 도어락이 강제로 해제되었습니다 | F218: =D218 -> , | G218: ANY_DOOR_LOCK_IS_FORCE_RELEASED | H218: =D218 -> , | I218: ANY_DOOR_LOCK_IS_FORCE_RELEASED | J218: =F218 -> , | K218: ANY_DOOR_LOCK_IS_FORCE_RELEASED | L218: =H218 -> , | M218: 도어락 상태를 확인해주세요. | N218: =J218 -> , | O218: CHECK DOOR LOCK STATUS. | P218: =L218 -> , | Q218: CHECK DOOR LOCK STATUS. | R218: =N218 -> , | S218: CHECK DOOR LOCK STATUS. | T218: =P218 -> , | U218: HEAVY | V218: =R218 -> , | W218: SAFETY | X218: , | Y218: SQUARE | Z218: , | AA218: 0 | AB218: , | AC218: 0 | AD218: , | AE218: 0 | AF218: , | AG218: 0 | AJ218: =VLOOKUP(Sheet1!W218,'알람 범위'!$D$2:$F$45,3,FALSE) -> 30000 | AK218: 106 | AL218: =AJ218+AK218 -> 30106 | AM218: =C218 -> DO_MAIN_ANY_DOOR_FORECE_RELEASED_X02A
A219: =AL219 -> 40000 | B219: , | C219: EF_PREFORM4_MAIN_EQUIPMENT_SILENT_STOP | D219: , | E219: 설비에서 무언 정지가 발생 했습니다 | F219: =D219 -> , | G219: THERE_WAS_A_SILENT_STOP_AT_THE_EQUIPMENT | H219: =D219 -> , | I219: THERE_WAS_A_SILENT_STOP_AT_THE_EQUIPMENT | J219: =F219 -> , | K219: THERE_WAS_A_SILENT_STOP_AT_THE_EQUIPMENT | L219: =H219 -> , | M219: 설비 상태를 확인해주세요. | N219: =J219 -> , | O219: CHECK THE EQUIPMENT STATUS. | P219: =L219 -> , | Q219: CHECK THE EQUIPMENT STATUS. | R219: =N219 -> , | S219: CHECK THE EQUIPMENT STATUS. | T219: =P219 -> , | U219: HEAVY | V219: =R219 -> , | W219: ETC | X219: , | Y219: SQUARE | Z219: , | AA219: 0 | AB219: , | AC219: 0 | AD219: , | AE219: 0 | AF219: , | AG219: 0 | AJ219: =VLOOKUP(Sheet1!W219,'알람 범위'!$D$2:$F$45,3,FALSE) -> 40000 | AK219: 0 | AL219: =AJ219+AK219 -> 40000 | AM219: =C219 -> EF_PREFORM4_MAIN_EQUIPMENT_SILENT_STOP
A220: =AL220 -> 40001 | B220: , | C220: EF_IN_SHUTTLE_CELL_DAMAGED_CHECK | D220: , | E220: 투입 셔틀 셀의 손상 유무를 확인 하세요 | F220: , | G220: CHECK_THE_CELL_FOR_DAMAGE(IN SHUTTLE) | H220: , | I220: CHECK_THE_CELL_FOR_DAMAGE(IN SHUTTLE) | J220: , | K220: CHECK_THE_CELL_FOR_DAMAGE(IN SHUTTLE) | L220: , | M220: 셀의 손상 유무를 확인 하세요 | N220: , | O220: CHECK THE CELL FOR DAMAGE | P220: , | Q220: CHECK THE CELL FOR DAMAGE | R220: , | S220: CHECK THE CELL FOR DAMAGE | T220: , | U220: LIGHT | V220: , | W220: ETC | X220: , | Y220: SQUARE | Z220: , | AA220: 0.0176565 | AB220: , | AC220: 0.453125 | AD220: , | AE220: 0.5184591 | AF220: , | AG220: 0.1315104 | AJ220: =VLOOKUP(Sheet1!W220,'알람 범위'!$D$2:$F$45,3,FALSE) -> 40000 | AK220: 1 | AL220: =AJ220+AK220 -> 40001 | AM220: =C220 -> EF_IN_SHUTTLE_CELL_DAMAGED_CHECK
...

Sheet 알람 범위
A1: 알람 범위 | B1: 알람 종류 | C1: 세부 범위 | D1: 알람 유닛
A2: 10000 ~ 29999 | B2: 시퀀스 알람 | C2: 10000 ~ 10499 | D2: LOAD_EQ_TO_EQ | F2: =LEFT($C2,5) -> 10000
C3: 10500 ~ 10999 | D3: IN_SHUTTLE | F3: =LEFT($C3,5) -> 10500
C4: 11000 ~ 11499 | D4: IN_ROBOT | F4: =LEFT($C4,5) -> 11000
C5: 11500 ~ 11999 | D5: INSPECTION_STAGE | F5: =LEFT($C5,5) -> 11500
C6: 12000 ~ 12499 | D6: OUT_ROBOT | F6: =LEFT($C6,5) -> 12000
C7: 13000 ~ 13499 | D7: OUT_FLIP | F7: =LEFT($C7,5) -> 13000
C8: 13500 ~ 13999 | D8: OUT_CONVEYOR | F8: =LEFT($C8,5) -> 13500
C9: 14000 ~ 14499 | D9: UNLOAD_EQ_TO_EQ | F9: =LEFT($C9,5) -> 14000
C10: 14500 ~ 14999 | F10: =LEFT($C10,5) -> 14500
C11: 15000 ~ 15499 | F11: =LEFT($C11,5) -> 15000
C12: 15500 ~ 15999 | F12: =LEFT($C12,5) -> 15500
C13: 16000 ~ 16499 | F13: =LEFT($C13,5) -> 16000
C14: 16500 ~ 16999 | F14: =LEFT($C14,5) -> 16500
C15: 17000 ~ 17499 | F15: =LEFT($C15,5) -> 17000
C16: 17500 ~ 17999 | F16: =LEFT($C16,5) -> 17500
C17: 18000 ~ 18499 | F17: =LEFT($C17,5) -> 18000
C18: 18500 ~ 18999 | F18: =LEFT($C18,5) -> 18500
C19: 19000 ~ 19499 | F19: =LEFT($C19,5) -> 19000
C20: 19500 ~ 19999 | F20: =LEFT($C20,5) -> 19500
C21: 20000 ~ 20499 | D21: MCR | F21: =LEFT($C21,5) -> 20000
C22: 20500 ~ 20999 | D22: PRE_ALIGN_VISION | F22: =LEFT($C22,5) -> 20500
C23: 21000 ~ 21499 | D23: INSPECT_VISION | F23: =LEFT($C23,5) -> 21000
C24: 21500 ~ 21999 | F24: =LEFT($C24,5) -> 21500
C25: 22000 ~ 22499 | F25: =LEFT($C25,5) -> 22000
C26: 22500 ~ 22999 | F26: =LEFT($C26,5) -> 22500
C27: 23000 ~ 23499 | F27: =LEFT($C27,5) -> 23000
C28: 23500 ~ 23999 | F28: =LEFT($C28,5) -> 23500
C29: 24000 ~ 24499 | F29: =LEFT($C29,5) -> 24000
C30: 28000 ~ 28499 | F30: =LEFT($C30,5) -> 28000
C31: 28500 ~ 28999 | F31: =LEFT($C31,5) -> 28500
C32: 29000 ~ 29499 | F32: =LEFT($C32,5) -> 29000
C33: 29500 ~ 29999 | D33: CIM | F33: =LEFT($C33,5) -> 29500
A34: 30000 ~ 39999 | B34: 장비 상태 알람 | C34: 30000 ~ 30999 | D34: SAFETY | F34: =LEFT($C34,5) -> 30000
C35: 31000 ~ 31999 | D35: MACHINE_STATE | F35: =LEFT($C35,5) -> 31000
F36: =LEFT($C36,5)
F37: =LEFT($C37,5)
F38: =LEFT($C38,5)
F39: =LEFT($C39,5)
F40: =LEFT($C40,5)
...

Sheet EnumMaker
V1: /// | W1: /// <summary> | X1: /// </summary> | Z1: ////////////////////////////////////////////////////////////////////////// | AA1: //
A2: =IF(ISBLANK(Sheet1!C2),"",SUBSTITUTE(SUBSTITUTE(SUBSTITUTE(SUBSTITUTE(SUBSTITUTE(Sheet1!C2, " ", "_"), "-", "_"), "&", "_"), "/", "_"), "#", "_")) -> EM_UPPER_EQUIPMENT_N_EMERGENCY_STATE | B2: =IF(ISBLANK(Sheet1!A2)=TRUE,"",IF(EXACT(Sheet1!W1,Sheet1!W2)=TRUE,"",$Z$1&CHAR(13)&$AA$1&Sheet1!W2&CHAR(13)&$Z$1&CHAR(13))&$W$1&CHAR(13)&$V$1&Sheet1!E2&CHAR(13)&$X$1&CHAR(13)&$A2&" = "&Sheet1!A2&",") -> //////////////////////////////////////////////////////////////////////////_x000D_// LOAD_EQ_TO_EQ_x000D_//////////////////////////////////////////////////////////////////////////_x000D_/// <summary>_x000D_/// 상류설비에서 EMERGENCY가 발생했습니다_x000D_/// </summary>_x000D_EM_UPPER_EQUIPMENT_N_EMERGENCY_STATE = 10000,
A3: =IF(ISBLANK(Sheet1!C3),"",SUBSTITUTE(SUBSTITUTE(SUBSTITUTE(SUBSTITUTE(SUBSTITUTE(Sheet1!C3, " ", "_"), "-", "_"), "&", "_"), "/", "_"), "#", "_")) -> EM_UPPER_EQUIPMENT_DOOR_OPEN | B3: =IF(ISBLANK(Sheet1!A3)=TRUE,"",IF(EXACT(Sheet1!W2,Sheet1!W3)=TRUE,"",$Z$1&CHAR(13)&$AA$1&Sheet1!W3&CHAR(13)&$Z$1&CHAR(13))&$W$1&CHAR(13)&$V$1&Sheet1!E3&CHAR(13)&$X$1&CHAR(13)&$A3&" = "&Sheet1!A3&",") -> /// <summary>_x000D_/// 상류설비에 DOOR가 열렸습니다_x000D_/// </summary>_x000D_EM_UPPER_EQUIPMENT_DOOR_OPEN = 10001,
A4: =IF(ISBLANK(Sheet1!C4),"",SUBSTITUTE(SUBSTITUTE(SUBSTITUTE(SUBSTITUTE(SUBSTITUTE(Sheet1!C4, " ", "_"), "-", "_"), "&", "_"), "/", "_"), "#", "_")) -> MO_IN_SHUTTLE_X1_HOME_MOTION | B4: =IF(ISBLANK(Sheet1!A4)=TRUE,"",IF(EXACT(Sheet1!W3,Sheet1!W4)=TRUE,"",$Z$1&CHAR(13)&$AA$1&Sheet1!W4&CHAR(13)&$Z$1&CHAR(13))&$W$1&CHAR(13)&$V$1&Sheet1!E4&CHAR(13)&$X$1&CHAR(13)&$A4&" = "&Sheet1!A4&",") -> //////////////////////////////////////////////////////////////////////////_x000D_// IN_SHUTTLE_x000D_//////////////////////////////////////////////////////////////////////////_x000D_/// <summary>_x000D_/// IN셔틀 X1축이 홈 동작 진행에 실패 했습니다_x000D_/// </summary>_x000D_MO_IN_SHUTTLE_X1_HOME_MOTION = 10500,
A5: =IF(ISBLANK(Sheet1!C5),"",SUBSTITUTE(SUBSTITUTE(SUBSTITUTE(SUBSTITUTE(SUBSTITUTE(Sheet1!C5, " ", "_"), "-", "_"), "&", "_"), "/", "_"), "#", "_")) -> MO_IN_SHUTTLE_X1_LOAD_MOVE | B5: =IF(ISBLANK(Sheet1!A5)=TRUE,"",IF(EXACT(Sheet1!W4,Sheet1!W5)=TRUE,"",$Z$1&CHAR(13)&$AA$1&Sheet1!W5&CHAR(13)&$Z$1&CHAR(13))&$W$1&CHAR(13)&$V$1&Sheet1!E5&CHAR(13)&$X$1&CHAR(13)&$A5&" = "&Sheet1!A5&",") -> /// <summary>_x000D_/// IN셔틀 X1축 로드 위치 이동에 실패 했습니다 (상류설비 위치)_x000D_/// </summary>_x000D_MO_IN_SHUTTLE_X1_LOAD_MOVE = 10501,
A6: =IF(ISBLANK(Sheet1!C6),"",SUBSTITUTE(SUBSTITUTE(SUBSTITUTE(SUBSTITUTE(SUBSTITUTE(Sheet1!C6, " ", "_"), "-", "_"), "&", "_"), "/", "_"), "#", "_")) -> MO_IN_SHUTTLE_X1_SCAN_START_WAIT_MOVE | B6: =IF(ISBLANK(Sheet1!A6)=TRUE,"",IF(EXACT(Sheet1!W5,Sheet1!W6)=TRUE,"",$Z$1&CHAR(13)&$AA$1&Sheet1!W6&CHAR(13)&$Z$1&CHAR(13))&$W$1&CHAR(13)&$V$1&Sheet1!E6&CHAR(13)&$X$1&CHAR(13)&$A6&" = "&Sheet1!A6&",") -> /// <summary>_x000D_/// IN셔틀 X1축 스캔 시작 대기 위치 이동에 실패 했습니다_x000D_/// </summary>_x000D_MO_IN_SHUTTLE_X1_SCAN_START_WAIT_MOVE = 10502,
A7: =IF(ISBLANK(Sheet1!C7),"",SUBSTITUTE(SUBSTITUTE(SUBSTITUTE(SUBSTITUTE(SUBSTITUTE(Sheet1!C7, " ", "_"), "-", "_"), "&", "_"), "/", "_"), "#", "_")) -> MO_IN_SHUTTLE_X1_SCAN_TRIGGER_START_MOVE | B7: =IF(ISBLANK(Sheet1!A7)=TRUE,"",IF(EXACT(Sheet1!W6,Sheet1!W7)=TRUE,"",$Z$1&CHAR(13)&$AA$1&Sheet1!W7&CHAR(13)&$Z$1&CHAR(13))&$W$1&CHAR(13)&$V$1&Sheet1!E7&CHAR(13)&$X$1&CHAR(13)&$A7&" = "&Sheet1!A7&",") -> /// <summary>_x000D_/// IN셔틀 X1축 스캔 트리거 시작 위치 이동에 실패 했습니다_x000D_/// </summary>_x000D_MO_IN_SHUTTLE_X1_SCAN_TRIGGER_START_MOVE = 10503,
A8: =IF(ISBLANK(Sheet1!C8),"",SUBSTITUTE(SUBSTITUTE(SUBSTITUTE(SUBSTITUTE(SUBSTITUTE(Sheet1!C8, " ", "_"), "-", "_"), "&", "_"), "/", "_"), "#", "_")) -> MO_IN_SHUTTLE_X1_SCAN_TRIGGER_END_MOVE | B8: =IF(ISBLANK(Sheet1!A8)=TRUE,"",IF(EXACT(Sheet1!W7,Sheet1!W8)=TRUE,"",$Z$1&CHAR(13)&$AA$1&Sheet1!W8&CHAR(13)&$Z$1&CHAR(13))&$W$1&CHAR(13)&$V$1&Sheet1!E8&CHAR(13)&$X$1&CHAR(13)&$A8&" = "&Sheet1!A8&",") -> /// <summary>_x000D_/// IN셔틀 X1축 스캔 트리거 종료 위치 이동에 실패 했습니다_x000D_/// </summary>_x000D_MO_IN_SHUTTLE_X1_SCAN_TRIGGER_END_MOVE = 10504,
A9: =IF(ISBLANK(Sheet1!C9),"",SUBSTITUTE(SUBSTITUTE(SUBSTITUTE(SUBSTITUTE(SUBSTITUTE(Sheet1!C9, " ", "_"), "-", "_"), "&", "_"), "/", "_"), "#", "_")) -> MO_IN_SHUTTLE_X1_ALIGN_MOVE | B9: =IF(ISBLANK(Sheet1!A9)=TRUE,"",IF(EXACT(Sheet1!W8,Sheet1!W9)=TRUE,"",$Z$1&CHAR(13)&$AA$1&Sheet1!W9&CHAR(13)&$Z$1&CHAR(13))&$W$1&CHAR(13)&$V$1&Sheet1!E9&CHAR(13)&$X$1&CHAR(13)&$A9&" = "&Sheet1!A9&",") -> /// <summary>_x000D_/// IN셔틀 X1축 얼라인 위치 이동에 실패 했습니다_x000D_/// </summary>_x000D_MO_IN_SHUTTLE_X1_ALIGN_MOVE = 10505,
A10: =IF(ISBLANK(Sheet1!C10),"",SUBSTITUTE(SUBSTITUTE(SUBSTITUTE(SUBSTITUTE(SUBSTITUTE(Sheet1!C10, " ", "_"), "-", "_"), "&", "_"), "/", "_"), "#", "_")) -> MO_IN_SHUTTLE_X1_UNLOAD_MOVE | B10: =IF(ISBLANK(Sheet1!A10)=TRUE,"",IF(EXACT(Sheet1!W9,Sheet1!W10)=TRUE,"",$Z$1&CHAR(13)&$AA$1&Sheet1!W10&CHAR(13)&$Z$1&CHAR(13))&$W$1&CHAR(13)&$V$1&Sheet1!E10&CHAR(13)&$X$1&CHAR(13)&$A10&" = "&Sheet1!A10&",") -> /// <summary>_x000D_/// IN셔틀 X1축 언로드 위치 이동에 실패 했습니다 (IN로봇 위치)_x000D_/// </summary>_x000D_MO_IN_SHUTTLE_X1_UNLOAD_MOVE = 10506,
A11: =IF(ISBLANK(Sheet1!C11),"",SUBSTITUTE(SUBSTITUTE(SUBSTITUTE(SUBSTITUTE(SUBSTITUTE(Sheet1!C11, " ", "_"), "-", "_"), "&", "_"), "/", "_"), "#", "_")) -> VC_IN_SHUTTLE_P1_VACUUM | B11: =IF(ISBLANK(Sheet1!A11)=TRUE,"",IF(EXACT(Sheet1!W10,Sheet1!W11)=TRUE,"",$Z$1&CHAR(13)&$AA$1&Sheet1!W11&CHAR(13)&$Z$1&CHAR(13))&$W$1&CHAR(13)&$V$1&Sheet1!E11&CHAR(13)&$X$1&CHAR(13)&$A11&" = "&Sheet1!A11&",") -> /// <summary>_x000D_/// IN셔틀 P1 진공 흡착에 실패 했습니다_x000D_/// </summary>_x000D_VC_IN_SHUTTLE_P1_VACUUM = 10600,
A12: =IF(ISBLANK(Sheet1!C12),"",SUBSTITUTE(SUBSTITUTE(SUBSTITUTE(SUBSTITUTE(SUBSTITUTE(Sheet1!C12, " ", "_"), "-", "_"), "&", "_"), "/", "_"), "#", "_")) -> VC_IN_SHUTTLE_P1_BLOW | B12: =IF(ISBLANK(Sheet1!A12)=TRUE,"",IF(EXACT(Sheet1!W11,Sheet1!W12)=TRUE,"",$Z$1&CHAR(13)&$AA$1&Sheet1!W12&CHAR(13)&$Z$1&CHAR(13))&$W$1&CHAR(13)&$V$1&Sheet1!E12&CHAR(13)&$X$1&CHAR(13)&$A12&" = "&Sheet1!A12&",") -> /// <summary>_x000D_/// IN셔틀 P1 진공 파기에 실패 했습니다_x000D_/// </summary>_x000D_VC_IN_SHUTTLE_P1_BLOW = 10601,
A13: =IF(ISBLANK(Sheet1!C13),"",SUBSTITUTE(SUBSTITUTE(SUBSTITUTE(SUBSTITUTE(SUBSTITUTE(Sheet1!C13, " ", "_"), "-", "_"), "&", "_"), "/", "_"), "#", "_")) -> SE_IN_SHUTTLE_P1_VACUUM_CHECK | B13: =IF(ISBLANK(Sheet1!A13)=TRUE,"",IF(EXACT(Sheet1!W12,Sheet1!W13)=TRUE,"",$Z$1&CHAR(13)&$AA$1&Sheet1!W13&CHAR(13)&$Z$1&CHAR(13))&$W$1&CHAR(13)&$V$1&Sheet1!E13&CHAR(13)&$X$1&CHAR(13)&$A13&" = "&Sheet1!A13&",") -> /// <summary>_x000D_/// IN셔틀 P1 셀 확인에 실패 했습니다 (진공)_x000D_/// </summary>_x000D_SE_IN_SHUTTLE_P1_VACUUM_CHECK = 10602,
... A226: =IF(ISBLANK(Sheet1!C226),"",SUBSTITUTE(SUBSTITUTE(SUBSTITUTE(SUBSTITUTE(SUBSTITUTE(Sheet1!C226, " ", "_"), "-", "_"), "&", "_"), "/", "_"), "#", "_")) | B226: =IF(ISBLANK(Sheet1!A226)=TRUE,"",IF(EXACT(Sheet1!W225,Sheet1!W226)=TRUE,"",$Z$1&CHAR(13)&$AA$1&Sheet1!W226&CHAR(13)&$Z$1&CHAR(13))&$W$1&CHAR(13)&$V$1&Sheet1!E226&CHAR(13)&$X$1&CHAR(13)&$A226&" = "&Sheet1!A226&",")
B227: =IF(ISBLANK(Sheet1!A226)=TRUE,"",IF(EXACT(Sheet1!W225,Sheet1!W226)=TRUE,"",$Z$1&CHAR(13)&$AA$1&Sheet1!W226&CHAR(13)&$Z$1&CHAR(13))&$W$1&CHAR(13)&$V$1&Sheet1!E226&CHAR(13)&$X$1&CHAR(13)&$A227&" = "&Sheet1!A226&",")
B228: =IF(ISBLANK(Sheet1!A227)=TRUE,"",IF(EXACT(Sheet1!W226,Sheet1!W227)=TRUE,"",$Z$1&CHAR(13)&$AA$1&Sheet1!W227&CHAR(13)&$Z$1&CHAR(13))&$W$1&CHAR(13)&$V$1&Sheet1!E227&CHAR(13)&$X$1&CHAR(13)&$A228&" = "&Sheet1!A227&",")

Sheet OSS Alarm Sheet
A1: No | B1: ALID | C1: ALCD | D1: ALTX | E1: EQP & MODULEID | F1: 발생 UNITID | G1: Description
A2: =IF(B2=" "," ",ROW(A2)-1) -> 1 | B2: =Sheet1!A2 -> 10000 | C2: =IF(Sheet1!U2="HEAVY",2,1) -> 2 | D2: =Sheet1!C2 -> EM_UPPER_EQUIPMENT_N_EMERGENCY_STATE | F2: =Sheet1!W2 -> LOAD_EQ_TO_EQ | G2: =Sheet1!E2 -> 상류설비에서 EMERGENCY가 발생했습니다
A3: =IF(B3=" "," ",ROW(A3)-1) -> 2 | B3: =Sheet1!A3 -> 10001 | C3: =IF(Sheet1!U3="HEAVY",2,1) -> 1 | D3: =Sheet1!C3 -> EM_UPPER_EQUIPMENT_DOOR_OPEN | F3: =Sheet1!W3 -> LOAD_EQ_TO_EQ | G3: =Sheet1!E3 -> 상류설비에 DOOR가 열렸습니다
A4: =IF(B4=" "," ",ROW(A4)-1) -> 3 | B4: =Sheet1!A4 -> 10500 | C4: =IF(Sheet1!U4="HEAVY",2,1) -> 2 | D4: =Sheet1!C4 -> MO_IN_SHUTTLE_X1_HOME_MOTION | F4: =Sheet1!W4 -> IN_SHUTTLE | G4: =Sheet1!E4 -> IN셔틀 X1축이 홈 동작 진행에 실패 했습니다
A5: =IF(B5=" "," ",ROW(A5)-1) -> 4 | B5: =Sheet1!A5 -> 10501 | C5: =IF(Sheet1!U5="HEAVY",2,1) -> 2 | D5: =Sheet1!C5 -> MO_IN_SHUTTLE_X1_LOAD_MOVE | F5: =Sheet1!W5 -> IN_SHUTTLE | G5: =Sheet1!E5 -> IN셔틀 X1축 로드 위치 이동에 실패 했습니다 (상류설비 위치)
A6: =IF(B6=" "," ",ROW(A6)-1) -> 5 | B6: =Sheet1!A6 -> 10502 | C6: =IF(Sheet1!U6="HEAVY",2,1) -> 2 | D6: =Sheet1!C6 -> MO_IN_SHUTTLE_X1_SCAN_START_WAIT_MOVE | F6: =Sheet1!W6 -> IN_SHUTTLE | G6: =Sheet1!E6 -> IN셔틀 X1축 스캔 시작 대기 위치 이동에 실패 했습니다
A7: =IF(B7=" "," ",ROW(A7)-1) -> 6 | B7: =Sheet1!A7 -> 10503 | C7: =IF(Sheet1!U7="HEAVY",2,1) -> 2 | D7: =Sheet1!C7 -> MO_IN_SHUTTLE_X1_SCAN_TRIGGER_START_MOVE | F7: =Sheet1!W7 -> IN_SHUTTLE | G7: =Sheet1!E7 -> IN셔틀 X1축 스캔 트리거 시작 위치 이동에 실패 했습니다
A8: =IF(B8=" "," ",ROW(A8)-1) -> 7 | B8: =Sheet1!A8 -> 10504 | C8: =IF(Sheet1!U8="HEAVY",2,1) -> 2 | D8: =Sheet1!C8 -> MO_IN_SHUTTLE_X1_SCAN_TRIGGER_END_MOVE | F8: =Sheet1!W8 -> IN_SHUTTLE | G8: =Sheet1!E8 -> IN셔틀 X1축 스캔 트리거 종료 위치 이동에 실패 했습니다
A9: =IF(B9=" "," ",ROW(A9)-1) -> 8 | B9: =Sheet1!A9 -> 10505 | C9: =IF(Sheet1!U9="HEAVY",2,1) -> 2 | D9: =Sheet1!C9 -> MO_IN_SHUTTLE_X1_ALIGN_MOVE | F9: =Sheet1!W9 -> IN_SHUTTLE | G9: =Sheet1!E9 -> IN셔틀 X1축 얼라인 위치 이동에 실패 했습니다
A10: =IF(B10=" "," ",ROW(A10)-1) -> 9 | B10: =Sheet1!A10 -> 10506 | C10: =IF(Sheet1!U10="HEAVY",2,1) -> 2 | D10: =Sheet1!C10 -> MO_IN_SHUTTLE_X1_UNLOAD_MOVE | F10: =Sheet1!W10 -> IN_SHUTTLE | G10: =Sheet1!E10 -> IN셔틀 X1축 언로드 위치 이동에 실패 했습니다 (IN로봇 위치)
A11: =IF(B11=" "," ",ROW(A11)-1) -> 10 | B11: =Sheet1!A11 -> 10600 | C11: =IF(Sheet1!U11="HEAVY",2,1) -> 2 | D11: =Sheet1!C11 -> VC_IN_SHUTTLE_P1_VACUUM | F11: =Sheet1!W11 -> IN_SHUTTLE | G11: =Sheet1!E11 -> IN셔틀 P1 진공 흡착에 실패 했습니다
A12: =IF(B12=" "," ",ROW(A12)-1) -> 11 | B12: =Sheet1!A12 -> 10601 | C12: =IF(Sheet1!U12="HEAVY",2,1) -> 2 | D12: =Sheet1!C12 -> VC_IN_SHUTTLE_P1_BLOW | F12: =Sheet1!W12 -> IN_SHUTTLE | G12: =Sheet1!E12 -> IN셔틀 P1 진공 파기에 실패 했습니다
A13: =IF(B13=" "," ",ROW(A13)-1) -> 12 | B13: =Sheet1!A13 -> 10602 | C13: =IF(Sheet1!U13="HEAVY",2,1) -> 2 | D13: =Sheet1!C13 -> SE_IN_SHUTTLE_P1_VACUUM_CHECK | F13: =Sheet1!W13 -> IN_SHUTTLE | G13: =Sheet1!E13 -> IN셔틀 P1 셀 확인에 실패 했습니다 (진공)
... A227: =IF(B227=" "," ",ROW(A227)-1) -> 226 | B227: =Sheet1!A227 -> 0 | C227: =IF(Sheet1!U227="HEAVY",2,1) -> 1 | D227: =Sheet1!C227 -> 0 | F227: =Sheet1!W227 -> 0 | G227: =Sheet1!E227 -> 0

Sheet URCIS Alarm Sheet
A1: ALID | B1: ALCD | C1: ALTX | D1: DESCRIPTION | E1: ENABLED
A2: =IF(Sheet1!A2="", "", Sheet1!A2) -> 10000 | B2: =IF(Sheet1!U2="", "", IF(Sheet1!U2="HEAVY","SERIOUS","LIGHT")) -> SERIOUS | C2: =IF(Sheet1!C2="","",Sheet1!C2) -> EM_UPPER_EQUIPMENT_N_EMERGENCY_STATE | E2: =IF(A2="","","TRUE") -> TRUE
A3: =IF(Sheet1!A3="", "", Sheet1!A3) -> 10001 | B3: =IF(Sheet1!U3="", "", IF(Sheet1!U3="HEAVY","SERIOUS","LIGHT")) -> LIGHT | C3: =IF(Sheet1!C3="","",Sheet1!C3) -> EM_UPPER_EQUIPMENT_DOOR_OPEN | E3: =IF(A3="","","TRUE") -> TRUE
A4: =IF(Sheet1!A4="", "", Sheet1!A4) -> 10500 | B4: =IF(Sheet1!U4="", "", IF(Sheet1!U4="HEAVY","SERIOUS","LIGHT")) -> SERIOUS | C4: =IF(Sheet1!C4="","",Sheet1!C4) -> MO_IN_SHUTTLE_X1_HOME_MOTION | E4: =IF(A4="","","TRUE") -> TRUE
A5: =IF(Sheet1!A5="", "", Sheet1!A5) -> 10501 | B5: =IF(Sheet1!U5="", "", IF(Sheet1!U5="HEAVY","SERIOUS","LIGHT")) -> SERIOUS | C5: =IF(Sheet1!C5="","",Sheet1!C5) -> MO_IN_SHUTTLE_X1_LOAD_MOVE | E5: =IF(A5="","","TRUE") -> TRUE
A6: =IF(Sheet1!A6="", "", Sheet1!A6) -> 10502 | B6: =IF(Sheet1!U6="", "", IF(Sheet1!U6="HEAVY","SERIOUS","LIGHT")) -> SERIOUS | C6: =IF(Sheet1!C6="","",Sheet1!C6) -> MO_IN_SHUTTLE_X1_SCAN_START_WAIT_MOVE | E6: =IF(A6="","","TRUE") -> TRUE
A7: =IF(Sheet1!A7="", "", Sheet1!A7) -> 10503 | B7: =IF(Sheet1!U7="", "", IF(Sheet1!U7="HEAVY","SERIOUS","LIGHT")) -> SERIOUS | C7: =IF(Sheet1!C7="","",Sheet1!C7) -> MO_IN_SHUTTLE_X1_SCAN_TRIGGER_START_MOVE | E7: =IF(A7="","","TRUE") -> TRUE
A8: =IF(Sheet1!A8="", "", Sheet1!A8) -> 10504 | B8: =IF(Sheet1!U8="", "", IF(Sheet1!U8="HEAVY","SERIOUS","LIGHT")) -> SERIOUS | C8: =IF(Sheet1!C8="","",Sheet1!C8) -> MO_IN_SHUTTLE_X1_SCAN_TRIGGER_END_MOVE | E8: =IF(A8="","","TRUE") -> TRUE
A9: =IF(Sheet1!A9="", "", Sheet1!A9) -> 10505 | B9: =IF(Sheet1!U9="", "", IF(Sheet1!U9="HEAVY","SERIOUS","LIGHT")) -> SERIOUS | C9: =IF(Sheet1!C9="","",Sheet1!C9) -> MO_IN_SHUTTLE_X1_ALIGN_MOVE | E9: =IF(A9="","","TRUE") -> TRUE
A10: =IF(Sheet1!A10="", "", Sheet1!A10) -> 10506 | B10: =IF(Sheet1!U10="", "", IF(Sheet1!U10="HEAVY","SERIOUS","LIGHT")) -> SERIOUS | C10: =IF(Sheet1!C10="","",Sheet1!C10) -> MO_IN_SHUTTLE_X1_UNLOAD_MOVE | E10: =IF(A10="","","TRUE") -> TRUE
A11: =IF(Sheet1!A11="", "", Sheet1!A11) -> 10600 | B11: =IF(Sheet1!U11="", "", IF(Sheet1!U11="HEAVY","SERIOUS","LIGHT")) -> SERIOUS | C11: =IF(Sheet1!C11="","",Sheet1!C11) -> VC_IN_SHUTTLE_P1_VACUUM | E11: =IF(A11="","","TRUE") -> TRUE
A12: =IF(Sheet1!A12="", "", Sheet1!A12) -> 10601 | B12: =IF(Sheet1!U12="", "", IF(Sheet1!U12="HEAVY","SERIOUS","LIGHT")) -> SERIOUS | C12: =IF(Sheet1!C12="","",Sheet1!C12) -> VC_IN_SHUTTLE_P1_BLOW | E12: =IF(A12="","","TRUE") -> TRUE
A13: =IF(Sheet1!A13="", "", Sheet1!A13) -> 10602 | B13: =IF(Sheet1!U13="", "", IF(Sheet1!U13="HEAVY","SERIOUS","LIGHT")) -> SERIOUS | C13: =IF(Sheet1!C13="","",Sheet1!C13) -> SE_IN_SHUTTLE_P1_VACUUM_CHECK | E13: =IF(A13="","","TRUE") -> TRUE
... A224: =IF(Sheet1!A224="", "", Sheet1!A224) -> 40005 | B224: =IF(Sheet1!U224="", "", IF(Sheet1!U224="HEAVY","SERIOUS","LIGHT")) -> LIGHT | C224: =IF(Sheet1!C224="","",Sheet1!C224) -> EF_OUT_FLIP_CELL_DAMAGED_CHECK | E224: =IF(A224="","","TRUE") -> TRUE

Sheet Hellopeople Alarm Sheet
A1: ALID | B1: ALCD | C1: ALTX
A2: =IF(Sheet1!A2="", "", Sheet1!A2) -> 10000 | B2: =IF(Sheet1!U2="", "", IF(Sheet1!U2="HEAVY","2","1")) -> 2 | C2: =IF(Sheet1!C2="","",Sheet1!C2) -> EM_UPPER_EQUIPMENT_N_EMERGENCY_STATE
A3: =IF(Sheet1!A3="", "", Sheet1!A3) -> 10001 | B3: =IF(Sheet1!U3="", "", IF(Sheet1!U3="HEAVY","2","1")) -> 1 | C3: =IF(Sheet1!C3="","",Sheet1!C3) -> EM_UPPER_EQUIPMENT_DOOR_OPEN
A4: =IF(Sheet1!A4="", "", Sheet1!A4) -> 10500 | B4: =IF(Sheet1!U4="", "", IF(Sheet1!U4="HEAVY","2","1")) -> 2 | C4: =IF(Sheet1!C4="","",Sheet1!C4) -> MO_IN_SHUTTLE_X1_HOME_MOTION
A5: =IF(Sheet1!A5="", "", Sheet1!A5) -> 10501 | B5: =IF(Sheet1!U5="", "", IF(Sheet1!U5="HEAVY","2","1")) -> 2 | C5: =IF(Sheet1!C5="","",Sheet1!C5) -> MO_IN_SHUTTLE_X1_LOAD_MOVE
A6: =IF(Sheet1!A6="", "", Sheet1!A6) -> 10502 | B6: =IF(Sheet1!U6="", "", IF(Sheet1!U6="HEAVY","2","1")) -> 2 | C6: =IF(Sheet1!C6="","",Sheet1!C6) -> MO_IN_SHUTTLE_X1_SCAN_START_WAIT_MOVE
A7: =IF(Sheet1!A7="", "", Sheet1!A7) -> 10503 | B7: =IF(Sheet1!U7="", "", IF(Sheet1!U7="HEAVY","2","1")) -> 2 | C7: =IF(Sheet1!C7="","",Sheet1!C7) -> MO_IN_SHUTTLE_X1_SCAN_TRIGGER_START_MOVE
A8: =IF(Sheet1!A8="", "", Sheet1!A8) -> 10504 | B8: =IF(Sheet1!U8="", "", IF(Sheet1!U8="HEAVY","2","1")) -> 2 | C8: =IF(Sheet1!C8="","",Sheet1!C8) -> MO_IN_SHUTTLE_X1_SCAN_TRIGGER_END_MOVE
A9: =IF(Sheet1!A9="", "", Sheet1!A9) -> 10505 | B9: =IF(Sheet1!U9="", "", IF(Sheet1!U9="HEAVY","2","1")) -> 2 | C9: =IF(Sheet1!C9="","",Sheet1!C9) -> MO_IN_SHUTTLE_X1_ALIGN_MOVE
A10: =IF(Sheet1!A10="", "", Sheet1!A10) -> 10506 | B10: =IF(Sheet1!U10="", "", IF(Sheet1!U10="HEAVY","2","1")) -> 2 | C10: =IF(Sheet1!C10="","",Sheet1!C10) -> MO_IN_SHUTTLE_X1_UNLOAD_MOVE
A11: =IF(Sheet1!A11="", "", Sheet1!A11) -> 10600 | B11: =IF(Sheet1!U11="", "", IF(Sheet1!U11="HEAVY","2","1")) -> 2 | C11: =IF(Sheet1!C11="","",Sheet1!C11) -> VC_IN_SHUTTLE_P1_VACUUM
A12: =IF(Sheet1!A12="", "", Sheet1!A12) -> 10601 | B12: =IF(Sheet1!U12="", "", IF(Sheet1!U12="HEAVY","2","1")) -> 2 | C12: =IF(Sheet1!C12="","",Sheet1!C12) -> VC_IN_SHUTTLE_P1_BLOW
A13: =IF(Sheet1!A13="", "", Sheet1!A13) -> 10602 | B13: =IF(Sheet1!U13="", "", IF(Sheet1!U13="HEAVY","2","1")) -> 2 | C13: =IF(Sheet1!C13="","",Sheet1!C13) -> SE_IN_SHUTTLE_P1_VACUUM_CHECK
... A225: =IF(Sheet1!A225="", "", Sheet1!A225) | B225: =IF(Sheet1!U225="", "", IF(Sheet1!U225="HEAVY","2","1")) | C225: =IF(Sheet1!C225="","",Sheet1!C225)
