Workbook

Sheet Sheet1
A1: SVID | B1: , | C1: SVNAME | D1: , | E1: NAME_LENGTH | F1: , | G1: UNIT | H1: , | I1: MIN_VALUE | J1: , | K1: MAX_VALUE | L1: , | M1: APPROPRIATE_MIN_VALUE | N1: , | O1: APPROPRIATE_VALUE | P1: , | Q1: APPROPRIATE_MAX_VALUE | R1: , | S1: DESCRIPTION | T1: , | U1: REMARKS | W1: DATATYPE | Y1: UNITID
A2: 10000 | B2: , | C2: UTIL_CELL_ID | D2: , | E2: =LEN(C2) -> 12 | F2: , | H2: , | I2: N/A | J2: , | K2: N/A | L2: , | M2: N/A | N2: , | O2: N/A | P2: , | Q2: N/A | R2: , | S2: UTIL_CELL_ID | T2: , | U2: 년월일시분초 상시보고 | W2: STRING | Y2: UTIL
A3: 10001 | B3: , | C3: UTIL_STEP_ID | D3: , | E3: =LEN(C3) -> 12 | F3: , | H3: , | I3: 0 | J3: , | K3: 2 | L3: , | M3: N/A | N3: , | O3: N/A | P3: , | Q3: N/A | R3: , | S3: UTIL_STEP_ID | T3: , | U3: AUTO : 2 / STOP : 0 | W3: INTEGER | Y3: UTIL
A4: 10002 | B4: , | C4: USE_IN_ROBOT_MCR | D4: , | E4: =LEN(C4) -> 16 | F4: , | H4: , | I4: 0 | J4: , | K4: 1 | L4: , | M4: N/A | N4: , | O4: N/A | P4: , | Q4: N/A | R4: , | S4: USE_IN_ROBOT_MCR | T4: , | U4: IN_ROBOT MCR 사용 여부 (0: Not Use 1: Use) | W4: INTEGER | Y4: UTIL
A5: 10003 | B5: , | C5: USE_INSP_STAGE_MAIN_VISION | D5: , | E5: =LEN(C5) -> 26 | F5: , | H5: , | I5: 0 | J5: , | K5: 1 | L5: , | M5: N/A | N5: , | O5: N/A | P5: , | Q5: N/A | R5: , | S5: USE_INSP_STAGE_MAIN_VISION | T5: , | U5: 검사기 사용 여부 (0: Not Use 1: Use) | W5: INTEGER | Y5: VISION
A6: 10004 | B6: , | C6: RUN_EFU | D6: , | E6: =LEN(C6) -> 7 | F6: , | H6: , | I6: 0 | J6: , | K6: 1 | L6: , | M6: N/A | N6: , | O6: N/A | P6: , | Q6: N/A | R6: , | S6: RUN_EFU | T6: , | U6: EFU 동작 여부 (0: Not Run 1: Run) | W6: INTEGER | Y6: UTIL
A7: 10005 | B7: , | C7: EFU_RPM_1 | D7: , | E7: =LEN(C7) -> 9 | F7: , | G7: RPM | H7: , | I7: 0 | J7: , | K7: 1400 | L7: , | M7: 700 | N7: , | O7: 900 | P7: , | Q7: 1100 | R7: , | S7: EFU_RPM_1 | T7: , | U7: 설비 상부에 장착되는 EFU#1의 회전속도값 | W7: INTEGER | Y7: UTIL
A8: 10006 | B8: , | C8: MAIN_ELECTRICAL_TEMP | D8: , | E8: =LEN(C8) -> 20 | F8: , | G8: ℃ | H8: , | I8: 0 | J8: , | K8: 100 | L8: , | M8: 20 | N8: , | O8: 28 | P8: , | Q8: 40 | R8: , | S8: MAIN_ELECTRICAL_TEMP | T8: , | U8: MAIN 전장반 온도 | W8: FLOAT | Y8: UTIL
A9: 10007 | B9: , | C9: MAIN_PCRACK_TEMP | D9: , | E9: =LEN(C9) -> 16 | F9: , | G9: ℃ | H9: , | I9: 0 | J9: , | K9: 100 | L9: , | M9: 20 | N9: , | O9: 28 | P9: , | Q9: 40 | R9: , | S9: MAIN_PCRACK_TEMP | T9: , | U9: PC 랙 온도 | W9: FLOAT | Y9: UTIL
A10: 10008 | B10: , | C10: USE_IN_SHUTTLE_PRE_ALIGN | D10: , | E10: =LEN(C10) -> 24 | F10: , | H10: , | I10: 0 | J10: , | K10: 1 | L10: , | M10: N/A | N10: , | O10: N/A | P10: , | Q10: N/A | R10: , | S10: USE_IN_SHUTTLE_PRE_ALIGN | T10: , | U10: In Shuttle Pre-Align 사용 여부 | W10: INTEGER | Y10: VISION
A11: 10009 | B11: , | C11: IN_SHUTTLE_PRE_ALIGN_SCORE_SETTING | D11: , | E11: =LEN(C11) -> 34 | F11: , | G11: % | H11: , | I11: 0 | J11: , | K11: 100 | L11: , | M11: N/A | N11: , | O11: N/A | P11: , | Q11: N/A | R11: , | S11: IN_SHUTTLE_PRE_ALIGN_SCORE_SETTING | T11: , | U11: In Shuttle Pre-Align Score 인터락 세팅값 | W11: FLOAT | Y11: VISION
A12: 10010 | B12: , | C12: IN_SHUTTLE_P1_PRE_ALIGN_CELL_ID | D12: , | E12: =LEN(C12) -> 31 | F12: , | H12: , | I12: N/A | J12: , | K12: N/A | L12: , | M12: N/A | N12: , | O12: N/A | P12: , | Q12: N/A | R12: , | S12: IN_SHUTTLE_P1_PRE_ALIGN_CELL_ID | T12: , | U12: In Shuttle P1 Pre-Align Cell ID | W12: STRING | Y12: VISION
A13: 10011 | B13: , | C13: IN_SHUTTLE_P1_PRE_ALIGN_STEP_ID | D13: , | E13: =LEN(C13) -> 31 | F13: , | H13: , | I13: 0 | J13: , | K13: 2 | L13: , | M13: N/A | N13: , | O13: N/A | P13: , | Q13: N/A | R13: , | S13: IN_SHUTTLE_P1_PRE_ALIGN_STEP_ID | T13: , | U13: In Shuttle P1 Pre-Align Step ID | W13: INTEGER | Y13: VISION
A14: 10012 | B14: , | C14: IN_SHUTTLE_P1_PRE_ALIGN_DATA_SCORE | D14: , | E14: =LEN(C14) -> 34 | F14: , | G14: % | H14: , | I14: 0 | J14: , | K14: 100 | L14: , | M14: N/A | N14: , | O14: N/A | P14: , | Q14: N/A | R14: , | S14: IN_SHUTTLE_P1_PRE_ALIGN_DATA_SCORE | T14: , | U14: In Shuttle P1 Pre-Align Data Score | W14: FLOAT | Y14: VISION
A15: 10013 | B15: , | C15: IN_SHUTTLE_P1_PRE_ALIGN_DATA_X | D15: , | E15: =LEN(C15) -> 30 | F15: , | G15: mm | H15: , | I15: -999 | J15: , | K15: 999 | L15: , | M15: N/A | N15: , | O15: N/A | P15: , | Q15: N/A | R15: , | S15: IN_SHUTTLE_P1_PRE_ALIGN_DATA_X | T15: , | U15: In Shuttle P1 Pre-Align Data X | W15: FLOAT | Y15: VISION
A16: 10014 | B16: , | C16: IN_SHUTTLE_P1_PRE_ALIGN_DATA_Y | D16: , | E16: =LEN(C16) -> 30 | F16: , | G16: mm | H16: , | I16: -999 | J16: , | K16: 999 | L16: , | M16: N/A | N16: , | O16: N/A | P16: , | Q16: N/A | R16: , | S16: IN_SHUTTLE_P1_PRE_ALIGN_DATA_Y | T16: , | U16: In Shuttle P1 Pre-Align Data Y | W16: FLOAT | Y16: VISION
A17: 10015 | B17: , | C17: IN_SHUTTLE_P1_PRE_ALIGN_DATA_T | D17: , | E17: =LEN(C17) -> 30 | F17: , | G17: º | H17: , | I17: -999 | J17: , | K17: 999 | L17: , | M17: N/A | N17: , | O17: N/A | P17: , | Q17: N/A | R17: , | S17: IN_SHUTTLE_P1_PRE_ALIGN_DATA_T | T17: , | U17: In Shuttle P1 Pre-Align Data T | W17: FLOAT | Y17: VISION
A18: 10016 | B18: , | C18: IN_SHUTTLE_P2_PRE_ALIGN_CELL_ID | D18: , | E18: =LEN(C18) -> 31 | F18: , | H18: , | I18: N/A | J18: , | K18: N/A | L18: , | M18: N/A | N18: , | O18: N/A | P18: , | Q18: N/A | R18: , | S18: IN_SHUTTLE_P2_PRE_ALIGN_CELL_ID | T18: , | U18: In Shuttle P2 Pre-Align Cell ID | W18: STRING | Y18: VISION
A19: 10017 | B19: , | C19: IN_SHUTTLE_P2_PRE_ALIGN_STEP_ID | D19: , | E19: =LEN(C19) -> 31 | F19: , | H19: , | I19: 0 | J19: , | K19: 2 | L19: , | M19: N/A | N19: , | O19: N/A | P19: , | Q19: N/A | R19: , | S19: IN_SHUTTLE_P2_PRE_ALIGN_STEP_ID | T19: , | U19: In Shuttle P2 Pre-Align Step ID | W19: INTEGER | Y19: VISION
A20: 10018 | B20: , | C20: IN_SHUTTLE_P2_PRE_ALIGN_DATA_SCORE | D20: , | E20: =LEN(C20) -> 34 | F20: , | G20: % | H20: , | I20: 0 | J20: , | K20: 100 | L20: , | M20: N/A | N20: , | O20: N/A | P20: , | Q20: N/A | R20: , | S20: IN_SHUTTLE_P2_PRE_ALIGN_DATA_SCORE | T20: , | U20: In Shuttle P2 Pre-Align Data Score | W20: FLOAT | Y20: VISION
A21: 10019 | B21: , | C21: IN_SHUTTLE_P2_PRE_ALIGN_DATA_X | D21: , | E21: =LEN(C21) -> 30 | F21: , | G21: mm | H21: , | I21: -999 | J21: , | K21: 999 | L21: , | M21: N/A | N21: , | O21: N/A | P21: , | Q21: N/A | R21: , | S21: IN_SHUTTLE_P2_PRE_ALIGN_DATA_X | T21: , | U21: In Shuttle P2 Pre-Align Data X | W21: FLOAT | Y21: VISION
A22: 10020 | B22: , | C22: IN_SHUTTLE_P2_PRE_ALIGN_DATA_Y | D22: , | E22: =LEN(C22) -> 30 | F22: , | G22: mm | H22: , | I22: -999 | J22: , | K22: 999 | L22: , | M22: N/A | N22: , | O22: N/A | P22: , | Q22: N/A | R22: , | S22: IN_SHUTTLE_P2_PRE_ALIGN_DATA_Y | T22: , | U22: In Shuttle P2 Pre-Align Data Y | W22: FLOAT | Y22: VISION
A23: 10021 | B23: , | C23: IN_SHUTTLE_P2_PRE_ALIGN_DATA_T | D23: , | E23: =LEN(C23) -> 30 | F23: , | G23: º | H23: , | I23: -999 | J23: , | K23: 999 | L23: , | M23: N/A | N23: , | O23: N/A | P23: , | Q23: N/A | R23: , | S23: IN_SHUTTLE_P2_PRE_ALIGN_DATA_T | T23: , | U23: In Shuttle P2 Pre-Align Data T | W23: FLOAT | Y23: VISION
A24: 10022 | B24: , | C24: MAIN_VACUUM_PRESSURE | D24: , | E24: =LEN(C24) -> 20 | F24: , | G24: kPa | H24: , | I24: -90 | J24: , | K24: 0 | L24: , | M24: -60 | N24: , | O24: -50 | P24: , | Q24: -40 | R24: , | S24: MAIN_VACUUM_PRESSURE | T24: , | U24: 설비에 공급되는 Main Vacuum에 대한 압력값 | W24: FLOAT | Y24: UTIL
A25: 10023 | B25: , | C25: INSP_STAGE_MAIN_VACUUM_PRESSURE | D25: , | E25: =LEN(C25) -> 31 | F25: , | G25: kPa | H25: , | I25: -90 | J25: , | K25: 0 | L25: , | M25: -60 | N25: , | O25: -50 | P25: , | Q25: -40 | R25: , | S25: INSP_STAGE_MAIN_VACUUM_PRESSURE | T25: , | U25: 설비에 공급되는 검사스테이지 Main Vacuum에 대한 압력값 | W25: FLOAT | Y25: UTIL
A26: 10024 | B26: , | C26: MAIN_CDA_PRESSURE | D26: , | E26: =LEN(C26) -> 17 | F26: , | G26: MPa | H26: , | I26: 0 | J26: , | K26: 0.7 | L26: , | M26: 0.35 | N26: , | O26: 0.5 | P26: , | Q26: 0.65 | R26: , | S26: MAIN_CDA_PRESSURE | T26: , | U26: 설비에 공급되는 Main Air에 대한 압력값 | W26: FLOAT | Y26: UTIL
A27: 10025 | B27: , | C27: IN_SHUTTLE_P1_CELL_ID | D27: , | E27: =LEN(C27) -> 21 | F27: , | H27: , | I27: N/A | J27: , | K27: N/A | L27: , | M27: N/A | N27: , | O27: N/A | P27: , | Q27: N/A | R27: , | S27: IN_SHUTTLE_P1_CELL_ID | T27: , | U27: IN SHUTTLE #1의 CELL ID | W27: STRING | Y27: IN SHUTTLE
A28: 10026 | B28: , | C28: IN_SHUTTLE_P1_STEP_ID | D28: , | E28: =LEN(C28) -> 21 | F28: , | H28: , | I28: 0 | J28: , | K28: 2 | L28: , | M28: N/A | N28: , | O28: N/A | P28: , | Q28: N/A | R28: , | S28: IN_SHUTTLE_P1_STEP_ID | T28: , | U28: IN SHUTTLE #1의 STEP ID | W28: INTEGER | Y28: IN SHUTTLE
A29: 10027 | B29: , | C29: IN_SHUTTLE_P1_VACUUM_PRESSURE | D29: , | E29: =LEN(C29) -> 29 | F29: , | G29: kPa | H29: , | I29: -70 | J29: , | K29: 0 | L29: , | M29: -60 | N29: , | O29: -50 | P29: , | Q29: -40 | R29: , | S29: IN_SHUTTLE_P1_VACUUM_PRESSURE | T29: , | U29: IN SHUTTLE #1의 모듈 흡착용 Vacuum 압력값 | W29: FLOAT | Y29: IN SHUTTLE
A30: 10028 | B30: , | C30: IN_SHUTTLE_P2_CELL_ID | D30: , | E30: =LEN(C30) -> 21 | F30: , | H30: , | I30: N/A | J30: , | K30: N/A | L30: , | M30: N/A | N30: , | O30: N/A | P30: , | Q30: N/A | R30: , | S30: IN_SHUTTLE_P2_CELL_ID | T30: , | U30: IN SHUTTLE #2의 CELL ID | W30: STRING | Y30: IN SHUTTLE
A31: 10029 | B31: , | C31: IN_SHUTTLE_P2_STEP_ID | D31: , | E31: =LEN(C31) -> 21 | F31: , | H31: , | I31: 0 | J31: , | K31: 2 | L31: , | M31: N/A | N31: , | O31: N/A | P31: , | Q31: N/A | R31: , | S31: IN_SHUTTLE_P2_STEP_ID | T31: , | U31: IN SHUTTLE #2의 STEP ID | W31: INTEGER | Y31: IN SHUTTLE
A32: 10030 | B32: , | C32: IN_SHUTTLE_P2_VACUUM_PRESSURE | D32: , | E32: =LEN(C32) -> 29 | F32: , | G32: kPa | H32: , | I32: -70 | J32: , | K32: 0 | L32: , | M32: -60 | N32: , | O32: -50 | P32: , | Q32: -40 | R32: , | S32: IN_SHUTTLE_P2_VACUUM_PRESSURE | T32: , | U32: IN SHUTTLE #2의 모듈 흡착용 Vacuum 압력값 | W32: FLOAT | Y32: IN SHUTTLE
A33: 10031 | B33: , | C33: IN_ROBOT_P1_CELL_ID | D33: , | E33: =LEN(C33) -> 19 | F33: , | H33: , | I33: 0 | J33: , | K33: 2 | L33: , | M33: N/A | N33: , | O33: N/A | P33: , | Q33: N/A | R33: , | S33: IN_ROBOT_P1_CELL_ID | T33: , | U33: IN ROBOT #1의 CELL ID | W33: STRING | Y33: IN ROBOT
A34: 10032 | B34: , | C34: IN_ROBOT_P1_STEP_ID | D34: , | E34: =LEN(C34) -> 19 | F34: , | H34: , | I34: N/A | J34: , | K34: N/A | L34: , | M34: N/A | N34: , | O34: N/A | P34: , | Q34: N/A | R34: , | S34: IN_ROBOT_P1_STEP_ID | T34: , | U34: IN ROBOT #1의 STEP ID | W34: INTEGER | Y34: IN ROBOT
A35: 10033 | B35: , | C35: IN_ROBOT_P1_VACUUM_PRESSURE | D35: , | E35: =LEN(C35) -> 27 | F35: , | G35: kPa | H35: , | I35: -70 | J35: , | K35: 0 | L35: , | M35: -60 | N35: , | O35: -50 | P35: , | Q35: -40 | R35: , | S35: IN_ROBOT_P1_VACUUM_PRESSURE | T35: , | U35: IN ROBOT #1의 모듈 흡착용 Vacuum 압력값 | W35: FLOAT | Y35: IN ROBOT
A36: 10034 | B36: , | C36: IN_ROBOT_P2_CELL_ID | D36: , | E36: =LEN(C36) -> 19 | F36: , | H36: , | I36: 0 | J36: , | K36: 2 | L36: , | M36: N/A | N36: , | O36: N/A | P36: , | Q36: N/A | R36: , | S36: IN_ROBOT_P2_CELL_ID | T36: , | U36: IN ROBOT #2의 CELL ID | W36: STRING | Y36: IN ROBOT
A37: 10035 | B37: , | C37: IN_ROBOT_P2_STEP_ID | D37: , | E37: =LEN(C37) -> 19 | F37: , | H37: , | I37: N/A | J37: , | K37: N/A | L37: , | M37: N/A | N37: , | O37: N/A | P37: , | Q37: N/A | R37: , | S37: IN_ROBOT_P2_STEP_ID | T37: , | U37: IN ROBOT #2의 STEP ID | W37: INTEGER | Y37: IN ROBOT
A38: 10036 | B38: , | C38: IN_ROBOT_P2_VACUUM_PRESSURE | D38: , | E38: =LEN(C38) -> 27 | F38: , | G38: kPa | H38: , | I38: -70 | J38: , | K38: 0 | L38: , | M38: -60 | N38: , | O38: -50 | P38: , | Q38: -40 | R38: , | S38: IN_ROBOT_P2_VACUUM_PRESSURE | T38: , | U38: IN ROBOT #2의 모듈 흡착용 Vacuum 압력값 | W38: FLOAT | Y38: IN ROBOT
A39: 10037 | B39: , | C39: INSP_STAGE_P1_CELL_ID | D39: , | E39: =LEN(C39) -> 21 | F39: , | H39: , | I39: N/A | J39: , | K39: N/A | L39: , | M39: N/A | N39: , | O39: N/A | P39: , | Q39: N/A | R39: , | S39: INSP_STAGE_P1_CELL_ID | T39: , | U39: INSP STAGE #1의 CELL ID | W39: STRING | Y39: INSP STAGE
A40: 10038 | B40: , | C40: INSP_STAGE_P1_STEP_ID | D40: , | E40: =LEN(C40) -> 21 | F40: , | H40: , | I40: 0 | J40: , | K40: 2 | L40: , | M40: N/A | N40: , | O40: N/A | P40: , | Q40: N/A | R40: , | S40: INSP_STAGE_P1_STEP_ID | T40: , | U40: INSP STAGE #1의 STEP ID | W40: INTEGER | Y40: INSP STAGE
...

Sheet Def
A1: DataType
A2: FLOAT
A3: STRING
A4: INTEGER

Sheet OSS SVID Sheet
A1: SVID | B1: SVNAME (ASCII 40) | C1: Name Length | D1: EQPID & MODULEID | E1: 발생 UNITID | F1: Unit(단위) | G1: MIN(최소값) | H1: MAX(최대값) | I1: 적정 최소값 | J1: 적정값 | K1: 적정 최대값 | L1: DATA TYPE | M1: MIN DSPR | N1: Description | O1: Remarks
A2: =Sheet1!A2 -> 10000 | B2: =Sheet1!C2 -> UTIL_CELL_ID | C2: =Sheet1!E2 -> 12 | E2: =Sheet1!Y2 -> UTIL | F2: =Sheet1!G2 | G2: =Sheet1!I2 -> N/A | H2: =Sheet1!K2 -> N/A | I2: =Sheet1!M2 -> N/A | J2: =Sheet1!O2 -> N/A | K2: =Sheet1!Q2 -> N/A | L2: =Sheet1!W2 -> STRING | N2: =Sheet1!S2 -> UTIL_CELL_ID | O2: =Sheet1!U2 -> 년월일시분초 상시보고
A3: =Sheet1!A3 -> 10001 | B3: =Sheet1!C3 -> UTIL_STEP_ID | C3: =Sheet1!E3 -> 12 | E3: =Sheet1!Y3 -> UTIL | F3: =Sheet1!G3 | G3: =Sheet1!I3 -> 0 | H3: =Sheet1!K3 -> 2 | I3: =Sheet1!M3 -> N/A | J3: =Sheet1!O3 -> N/A | K3: =Sheet1!Q3 -> N/A | L3: =Sheet1!W3 -> INTEGER | N3: =Sheet1!S3 -> UTIL_STEP_ID | O3: =Sheet1!U3 -> AUTO : 2 / STOP : 0
A4: =Sheet1!A4 -> 10002 | B4: =Sheet1!C4 -> USE_IN_ROBOT_MCR | C4: =Sheet1!E4 -> 16 | E4: =Sheet1!Y4 -> UTIL | F4: =Sheet1!G4 | G4: =Sheet1!I4 -> 0 | H4: =Sheet1!K4 -> 1 | I4: =Sheet1!M4 -> N/A | J4: =Sheet1!O4 -> N/A | K4: =Sheet1!Q4 -> N/A | L4: =Sheet1!W4 -> INTEGER | N4: =Sheet1!S4 -> USE_IN_ROBOT_MCR | O4: =Sheet1!U4 -> IN_ROBOT MCR 사용 여부 (0: Not Use 1: Use)
A5: =Sheet1!A5 -> 10003 | B5: =Sheet1!C5 -> USE_INSP_STAGE_MAIN_VISION | C5: =Sheet1!E5 -> 26 | E5: =Sheet1!Y5 -> VISION | F5: =Sheet1!G5 | G5: =Sheet1!I5 -> 0 | H5: =Sheet1!K5 -> 1 | I5: =Sheet1!M5 -> N/A | J5: =Sheet1!O5 -> N/A | K5: =Sheet1!Q5 -> N/A | L5: =Sheet1!W5 -> INTEGER | N5: =Sheet1!S5 -> USE_INSP_STAGE_MAIN_VISION | O5: =Sheet1!U5 -> 검사기 사용 여부 (0: Not Use 1: Use)
A6: =Sheet1!A6 -> 10004 | B6: =Sheet1!C6 -> RUN_EFU | C6: =Sheet1!E6 -> 7 | E6: =Sheet1!Y6 -> UTIL | F6: =Sheet1!G6 | G6: =Sheet1!I6 -> 0 | H6: =Sheet1!K6 -> 1 | I6: =Sheet1!M6 -> N/A | J6: =Sheet1!O6 -> N/A | K6: =Sheet1!Q6 -> N/A | L6: =Sheet1!W6 -> INTEGER | N6: =Sheet1!S6 -> RUN_EFU | O6: =Sheet1!U6 -> EFU 동작 여부 (0: Not Run 1: Run)
A7: =Sheet1!A7 -> 10005 | B7: =Sheet1!C7 -> EFU_RPM_1 | C7: =Sheet1!E7 -> 9 | E7: =Sheet1!Y7 -> UTIL | F7: =Sheet1!G7 -> RPM | G7: =Sheet1!I7 -> 0 | H7: =Sheet1!K7 -> 1400 | I7: =Sheet1!M7 -> 700 | J7: =Sheet1!O7 -> 900 | K7: =Sheet1!Q7 -> 1100 | L7: =Sheet1!W7 -> INTEGER | N7: =Sheet1!S7 -> EFU_RPM_1 | O7: =Sheet1!U7 -> 설비 상부에 장착되는 EFU#1의 회전속도값
A8: =Sheet1!A8 -> 10006 | B8: =Sheet1!C8 -> MAIN_ELECTRICAL_TEMP | C8: =Sheet1!E8 -> 20 | E8: =Sheet1!Y8 -> UTIL | F8: =Sheet1!G8 -> ℃ | G8: =Sheet1!I8 -> 0 | H8: =Sheet1!K8 -> 100 | I8: =Sheet1!M8 -> 20 | J8: =Sheet1!O8 -> 28 | K8: =Sheet1!Q8 -> 40 | L8: =Sheet1!W8 -> FLOAT | N8: =Sheet1!S8 -> MAIN_ELECTRICAL_TEMP | O8: =Sheet1!U8 -> MAIN 전장반 온도
A9: =Sheet1!A9 -> 10007 | B9: =Sheet1!C9 -> MAIN_PCRACK_TEMP | C9: =Sheet1!E9 -> 16 | E9: =Sheet1!Y9 -> UTIL | F9: =Sheet1!G9 -> ℃ | G9: =Sheet1!I9 -> 0 | H9: =Sheet1!K9 -> 100 | I9: =Sheet1!M9 -> 20 | J9: =Sheet1!O9 -> 28 | K9: =Sheet1!Q9 -> 40 | L9: =Sheet1!W9 -> FLOAT | N9: =Sheet1!S9 -> MAIN_PCRACK_TEMP | O9: =Sheet1!U9 -> PC 랙 온도
A10: =Sheet1!A10 -> 10008 | B10: =Sheet1!C10 -> USE_IN_SHUTTLE_PRE_ALIGN | C10: =Sheet1!E10 -> 24 | E10: =Sheet1!Y10 -> VISION | F10: =Sheet1!G10 | G10: =Sheet1!I10 -> 0 | H10: =Sheet1!K10 -> 1 | I10: =Sheet1!M10 -> N/A | J10: =Sheet1!O10 -> N/A | K10: =Sheet1!Q10 -> N/A | L10: =Sheet1!W10 -> INTEGER | N10: =Sheet1!S10 -> USE_IN_SHUTTLE_PRE_ALIGN | O10: =Sheet1!U10 -> In Shuttle Pre-Align 사용 여부
A11: =Sheet1!A11 -> 10009 | B11: =Sheet1!C11 -> IN_SHUTTLE_PRE_ALIGN_SCORE_SETTING | C11: =Sheet1!E11 -> 34 | E11: =Sheet1!Y11 -> VISION | F11: =Sheet1!G11 -> % | G11: =Sheet1!I11 -> 0 | H11: =Sheet1!K11 -> 100 | I11: =Sheet1!M11 -> N/A | J11: =Sheet1!O11 -> N/A | K11: =Sheet1!Q11 -> N/A | L11: =Sheet1!W11 -> FLOAT | N11: =Sheet1!S11 -> IN_SHUTTLE_PRE_ALIGN_SCORE_SETTING | O11: =Sheet1!U11 -> In Shuttle Pre-Align Score 인터락 세팅값
A12: =Sheet1!A12 -> 10010 | B12: =Sheet1!C12 -> IN_SHUTTLE_P1_PRE_ALIGN_CELL_ID | C12: =Sheet1!E12 -> 31 | E12: =Sheet1!Y12 -> VISION | F12: =Sheet1!G12 | G12: =Sheet1!I12 -> N/A | H12: =Sheet1!K12 -> N/A | I12: =Sheet1!M12 -> N/A | J12: =Sheet1!O12 -> N/A | K12: =Sheet1!Q12 -> N/A | L12: =Sheet1!W12 -> STRING | N12: =Sheet1!S12 -> IN_SHUTTLE_P1_PRE_ALIGN_CELL_ID | O12: =Sheet1!U12 -> In Shuttle P1 Pre-Align Cell ID
A13: =Sheet1!A13 -> 10011 | B13: =Sheet1!C13 -> IN_SHUTTLE_P1_PRE_ALIGN_STEP_ID | C13: =Sheet1!E13 -> 31 | E13: =Sheet1!Y13 -> VISION | F13: =Sheet1!G13 | G13: =Sheet1!I13 -> 0 | H13: =Sheet1!K13 -> 2 | I13: =Sheet1!M13 -> N/A | J13: =Sheet1!O13 -> N/A | K13: =Sheet1!Q13 -> N/A | L13: =Sheet1!W13 -> INTEGER | N13: =Sheet1!S13 -> IN_SHUTTLE_P1_PRE_ALIGN_STEP_ID | O13: =Sheet1!U13 -> In Shuttle P1 Pre-Align Step ID
... A80: =Sheet1!A80 -> 0 | B80: =Sheet1!C80 -> 0 | C80: =Sheet1!E80 -> 0 | E80: =Sheet1!Y80 -> 0 | F80: =Sheet1!G80 -> 0 | G80: =Sheet1!I80 -> 0 | H80: =Sheet1!K80 -> 0 | I80: =Sheet1!M80 -> 0 | J80: =Sheet1!O80 -> 0 | K80: =Sheet1!Q80 -> 0 | L80: =Sheet1!W80 -> 0 | N80: =Sheet1!S80 -> 0 | O80: =Sheet1!U80 -> 0
A144: =IF(LEN(Sheet1!A365)=0, " ", Sheet1!A365) | B144: =IF(LEN(Sheet1!C365)=0, " ", Sheet1!C365) | C144: =IF(LEN(Sheet1!E365)=0, " ", Sheet1!E365) | F144: =IF(LEN(Sheet1!G365)=0, " ", Sheet1!G365) | G144: =IF(LEN(Sheet1!I365)=0, " ", Sheet1!I365) | H144: =IF(LEN(Sheet1!K365)=0, " ", Sheet1!K365) | I144: =IF(LEN(Sheet1!M365)=0, " ", Sheet1!M365) | J144: =IF(LEN(Sheet1!O365)=0, " ", Sheet1!O365) | K144: =IF(LEN(Sheet1!Q365)=0, " ", Sheet1!Q365) | L144: =IF(LEN(Sheet1!W365)=0, " ", Sheet1!W365) | N144: =IF(LEN(Sheet1!S365)=0, " ", Sheet1!S365) | O144: =IF(LEN(Sheet1!U365)=0, " ", Sheet1!U365)
A145: =IF(LEN(Sheet1!A366)=0, " ", Sheet1!A366) | B145: =IF(LEN(Sheet1!C366)=0, " ", Sheet1!C366) | C145: =IF(LEN(Sheet1!E366)=0, " ", Sheet1!E366) | F145: =IF(LEN(Sheet1!G366)=0, " ", Sheet1!G366) | G145: =IF(LEN(Sheet1!I366)=0, " ", Sheet1!I366) | H145: =IF(LEN(Sheet1!K366)=0, " ", Sheet1!K366) | I145: =IF(LEN(Sheet1!M366)=0, " ", Sheet1!M366) | J145: =IF(LEN(Sheet1!O366)=0, " ", Sheet1!O366) | K145: =IF(LEN(Sheet1!Q366)=0, " ", Sheet1!Q366) | L145: =IF(LEN(Sheet1!W366)=0, " ", Sheet1!W366) | N145: =IF(LEN(Sheet1!S366)=0, " ", Sheet1!S366) | O145: =IF(LEN(Sheet1!U366)=0, " ", Sheet1!U366)
A146: =IF(LEN(Sheet1!A367)=0, " ", Sheet1!A367) | B146: =IF(LEN(Sheet1!C367)=0, " ", Sheet1!C367) | C146: =IF(LEN(Sheet1!E367)=0, " ", Sheet1!E367) | F146: =IF(LEN(Sheet1!G367)=0, " ", Sheet1!G367) | G146: =IF(LEN(Sheet1!I367)=0, " ", Sheet1!I367) | H146: =IF(LEN(Sheet1!K367)=0, " ", Sheet1!K367) | I146: =IF(LEN(Sheet1!M367)=0, " ", Sheet1!M367) | J146: =IF(LEN(Sheet1!O367)=0, " ", Sheet1!O367) | K146: =IF(LEN(Sheet1!Q367)=0, " ", Sheet1!Q367) | L146: =IF(LEN(Sheet1!W367)=0, " ", Sheet1!W367) | N146: =IF(LEN(Sheet1!S367)=0, " ", Sheet1!S367) | O146: =IF(LEN(Sheet1!U367)=0, " ", Sheet1!U367)
A147: =IF(LEN(Sheet1!A368)=0, " ", Sheet1!A368) | B147: =IF(LEN(Sheet1!C368)=0, " ", Sheet1!C368) | C147: =IF(LEN(Sheet1!E368)=0, " ", Sheet1!E368) | F147: =IF(LEN(Sheet1!G368)=0, " ", Sheet1!G368) | G147: =IF(LEN(Sheet1!I368)=0, " ", Sheet1!I368) | H147: =IF(LEN(Sheet1!K368)=0, " ", Sheet1!K368) | I147: =IF(LEN(Sheet1!M368)=0, " ", Sheet1!M368) | J147: =IF(LEN(Sheet1!O368)=0, " ", Sheet1!O368) | K147: =IF(LEN(Sheet1!Q368)=0, " ", Sheet1!Q368) | L147: =IF(LEN(Sheet1!W368)=0, " ", Sheet1!W368) | N147: =IF(LEN(Sheet1!S368)=0, " ", Sheet1!S368) | O147: =IF(LEN(Sheet1!U368)=0, " ", Sheet1!U368)
A148: =IF(LEN(Sheet1!A369)=0, " ", Sheet1!A369) | B148: =IF(LEN(Sheet1!C369)=0, " ", Sheet1!C369) | C148: =IF(LEN(Sheet1!E369)=0, " ", Sheet1!E369) | F148: =IF(LEN(Sheet1!G369)=0, " ", Sheet1!G369) | G148: =IF(LEN(Sheet1!I369)=0, " ", Sheet1!I369) | H148: =IF(LEN(Sheet1!K369)=0, " ", Sheet1!K369) | I148: =IF(LEN(Sheet1!M369)=0, " ", Sheet1!M369) | J148: =IF(LEN(Sheet1!O369)=0, " ", Sheet1!O369) | K148: =IF(LEN(Sheet1!Q369)=0, " ", Sheet1!Q369) | L148: =IF(LEN(Sheet1!W369)=0, " ", Sheet1!W369) | N148: =IF(LEN(Sheet1!S369)=0, " ", Sheet1!S369) | O148: =IF(LEN(Sheet1!U369)=0, " ", Sheet1!U369)
A149: =IF(LEN(Sheet1!A370)=0, " ", Sheet1!A370) | B149: =IF(LEN(Sheet1!C370)=0, " ", Sheet1!C370) | C149: =IF(LEN(Sheet1!E370)=0, " ", Sheet1!E370) | F149: =IF(LEN(Sheet1!G370)=0, " ", Sheet1!G370) | G149: =IF(LEN(Sheet1!I370)=0, " ", Sheet1!I370) | H149: =IF(LEN(Sheet1!K370)=0, " ", Sheet1!K370) | I149: =IF(LEN(Sheet1!M370)=0, " ", Sheet1!M370) | J149: =IF(LEN(Sheet1!O370)=0, " ", Sheet1!O370) | K149: =IF(LEN(Sheet1!Q370)=0, " ", Sheet1!Q370) | L149: =IF(LEN(Sheet1!W370)=0, " ", Sheet1!W370) | N149: =IF(LEN(Sheet1!S370)=0, " ", Sheet1!S370) | O149: =IF(LEN(Sheet1!U370)=0, " ", Sheet1!U370)
A150: =IF(LEN(Sheet1!A371)=0, " ", Sheet1!A371) | B150: =IF(LEN(Sheet1!C371)=0, " ", Sheet1!C371) | C150: =IF(LEN(Sheet1!E371)=0, " ", Sheet1!E371) | F150: =IF(LEN(Sheet1!G371)=0, " ", Sheet1!G371) | G150: =IF(LEN(Sheet1!I371)=0, " ", Sheet1!I371) | H150: =IF(LEN(Sheet1!K371)=0, " ", Sheet1!K371) | I150: =IF(LEN(Sheet1!M371)=0, " ", Sheet1!M371) | J150: =IF(LEN(Sheet1!O371)=0, " ", Sheet1!O371) | K150: =IF(LEN(Sheet1!Q371)=0, " ", Sheet1!Q371) | L150: =IF(LEN(Sheet1!W371)=0, " ", Sheet1!W371) | N150: =IF(LEN(Sheet1!S371)=0, " ", Sheet1!S371) | O150: =IF(LEN(Sheet1!U371)=0, " ", Sheet1!U371)

Sheet Hellopeople SVID Sheet
A1: SVID | B1: SVNAME | C1: UNIT | D1: MIN | E1: MAX | F1: DATATYPE | G1: DESCRIPTION
A2: =Sheet1!A2 -> 10000 | B2: =Sheet1!C2 -> UTIL_CELL_ID | C2: =IFERROR(IF(OR(LEN(TRIM(Sheet1!G2))=0, Sheet1!G2="N/A"), "-", Sheet1!G2),"-") -> - | D2: =IFERROR(IF(OR(LEN(TRIM(Sheet1!I2))=0, Sheet1!I2="N/A"), "-", Sheet1!I2),"-") -> - | E2: =IFERROR(IF(OR(LEN(TRIM(Sheet1!K2))=0, Sheet1!K2="N/A"), "-", Sheet1!K2),"-") -> - | F2: =IF(Sheet1!W2="STRING","ASCII",IF(Sheet1!W2="INTEGER","FLOAT",Sheet1!W2)) -> ASCII | G2: =Sheet1!U2 -> 년월일시분초 상시보고
A3: =Sheet1!A3 -> 10001 | B3: =Sheet1!C3 -> UTIL_STEP_ID | C3: =IFERROR(IF(OR(LEN(TRIM(Sheet1!G3))=0, Sheet1!G3="N/A"), "-", Sheet1!G3),"-") -> - | D3: =IFERROR(IF(OR(LEN(TRIM(Sheet1!I3))=0, Sheet1!I3="N/A"), "-", Sheet1!I3),"-") -> 0 | E3: =IFERROR(IF(OR(LEN(TRIM(Sheet1!K3))=0, Sheet1!K3="N/A"), "-", Sheet1!K3),"-") -> 2 | F3: =IF(Sheet1!W3="STRING","ASCII",IF(Sheet1!W3="INTEGER","FLOAT",Sheet1!W3)) -> FLOAT | G3: =Sheet1!U3 -> AUTO : 2 / STOP : 0
A4: =Sheet1!A4 -> 10002 | B4: =Sheet1!C4 -> USE_IN_ROBOT_MCR | C4: =IFERROR(IF(OR(LEN(TRIM(Sheet1!G4))=0, Sheet1!G4="N/A"), "-", Sheet1!G4),"-") -> - | D4: =IFERROR(IF(OR(LEN(TRIM(Sheet1!I4))=0, Sheet1!I4="N/A"), "-", Sheet1!I4),"-") -> 0 | E4: =IFERROR(IF(OR(LEN(TRIM(Sheet1!K4))=0, Sheet1!K4="N/A"), "-", Sheet1!K4),"-") -> 1 | F4: =IF(Sheet1!W4="STRING","ASCII",IF(Sheet1!W4="INTEGER","FLOAT",Sheet1!W4)) -> FLOAT | G4: =Sheet1!U4 -> IN_ROBOT MCR 사용 여부 (0: Not Use 1: Use)
A5: =Sheet1!A5 -> 10003 | B5: =Sheet1!C5 -> USE_INSP_STAGE_MAIN_VISION | C5: =IFERROR(IF(OR(LEN(TRIM(Sheet1!G5))=0, Sheet1!G5="N/A"), "-", Sheet1!G5),"-") -> - | D5: =IFERROR(IF(OR(LEN(TRIM(Sheet1!I5))=0, Sheet1!I5="N/A"), "-", Sheet1!I5),"-") -> 0 | E5: =IFERROR(IF(OR(LEN(TRIM(Sheet1!K5))=0, Sheet1!K5="N/A"), "-", Sheet1!K5),"-") -> 1 | F5: =IF(Sheet1!W5="STRING","ASCII",IF(Sheet1!W5="INTEGER","FLOAT",Sheet1!W5)) -> FLOAT | G5: =Sheet1!U5 -> 검사기 사용 여부 (0: Not Use 1: Use)
A6: =Sheet1!A6 -> 10004 | B6: =Sheet1!C6 -> RUN_EFU | C6: =IFERROR(IF(OR(LEN(TRIM(Sheet1!G6))=0, Sheet1!G6="N/A"), "-", Sheet1!G6),"-") -> - | D6: =IFERROR(IF(OR(LEN(TRIM(Sheet1!I6))=0, Sheet1!I6="N/A"), "-", Sheet1!I6),"-") -> 0 | E6: =IFERROR(IF(OR(LEN(TRIM(Sheet1!K6))=0, Sheet1!K6="N/A"), "-", Sheet1!K6),"-") -> 1 | F6: =IF(Sheet1!W6="STRING","ASCII",IF(Sheet1!W6="INTEGER","FLOAT",Sheet1!W6)) -> FLOAT | G6: =Sheet1!U6 -> EFU 동작 여부 (0: Not Run 1: Run)
A7: =Sheet1!A7 -> 10005 | B7: =Sheet1!C7 -> EFU_RPM_1 | C7: =IFERROR(IF(OR(LEN(TRIM(Sheet1!G7))=0, Sheet1!G7="N/A"), "-", Sheet1!G7),"-") -> RPM | D7: =IFERROR(IF(OR(LEN(TRIM(Sheet1!I7))=0, Sheet1!I7="N/A"), "-", Sheet1!I7),"-") -> 0 | E7: =IFERROR(IF(OR(LEN(TRIM(Sheet1!K7))=0, Sheet1!K7="N/A"), "-", Sheet1!K7),"-") -> 1400 | F7: =IF(Sheet1!W7="STRING","ASCII",IF(Sheet1!W7="INTEGER","FLOAT",Sheet1!W7)) -> FLOAT | G7: =Sheet1!U7 -> 설비 상부에 장착되는 EFU#1의 회전속도값
A8: =Sheet1!A8 -> 10006 | B8: =Sheet1!C8 -> MAIN_ELECTRICAL_TEMP | C8: =IFERROR(IF(OR(LEN(TRIM(Sheet1!G8))=0, Sheet1!G8="N/A"), "-", Sheet1!G8),"-") -> ℃ | D8: =IFERROR(IF(OR(LEN(TRIM(Sheet1!I8))=0, Sheet1!I8="N/A"), "-", Sheet1!I8),"-") -> 0 | E8: =IFERROR(IF(OR(LEN(TRIM(Sheet1!K8))=0, Sheet1!K8="N/A"), "-", Sheet1!K8),"-") -> 100 | F8: =IF(Sheet1!W8="STRING","ASCII",IF(Sheet1!W8="INTEGER","FLOAT",Sheet1!W8)) -> FLOAT | G8: =Sheet1!U8 -> MAIN 전장반 온도
A9: =Sheet1!A9 -> 10007 | B9: =Sheet1!C9 -> MAIN_PCRACK_TEMP | C9: =IFERROR(IF(OR(LEN(TRIM(Sheet1!G9))=0, Sheet1!G9="N/A"), "-", Sheet1!G9),"-") -> ℃ | D9: =IFERROR(IF(OR(LEN(TRIM(Sheet1!I9))=0, Sheet1!I9="N/A"), "-", Sheet1!I9),"-") -> 0 | E9: =IFERROR(IF(OR(LEN(TRIM(Sheet1!K9))=0, Sheet1!K9="N/A"), "-", Sheet1!K9),"-") -> 100 | F9: =IF(Sheet1!W9="STRING","ASCII",IF(Sheet1!W9="INTEGER","FLOAT",Sheet1!W9)) -> FLOAT | G9: =Sheet1!U9 -> PC 랙 온도
A10: =Sheet1!A10 -> 10008 | B10: =Sheet1!C10 -> USE_IN_SHUTTLE_PRE_ALIGN | C10: =IFERROR(IF(OR(LEN(TRIM(Sheet1!G10))=0, Sheet1!G10="N/A"), "-", Sheet1!G10),"-") -> - | D10: =IFERROR(IF(OR(LEN(TRIM(Sheet1!I10))=0, Sheet1!I10="N/A"), "-", Sheet1!I10),"-") -> 0 | E10: =IFERROR(IF(OR(LEN(TRIM(Sheet1!K10))=0, Sheet1!K10="N/A"), "-", Sheet1!K10),"-") -> 1 | F10: =IF(Sheet1!W10="STRING","ASCII",IF(Sheet1!W10="INTEGER","FLOAT",Sheet1!W10)) -> FLOAT | G10: =Sheet1!U10 -> In Shuttle Pre-Align 사용 여부
A11: =Sheet1!A11 -> 10009 | B11: =Sheet1!C11 -> IN_SHUTTLE_PRE_ALIGN_SCORE_SETTING | C11: =IFERROR(IF(OR(LEN(TRIM(Sheet1!G11))=0, Sheet1!G11="N/A"), "-", Sheet1!G11),"-") -> % | D11: =IFERROR(IF(OR(LEN(TRIM(Sheet1!I11))=0, Sheet1!I11="N/A"), "-", Sheet1!I11),"-") -> 0 | E11: =IFERROR(IF(OR(LEN(TRIM(Sheet1!K11))=0, Sheet1!K11="N/A"), "-", Sheet1!K11),"-") -> 100 | F11: =IF(Sheet1!W11="STRING","ASCII",IF(Sheet1!W11="INTEGER","FLOAT",Sheet1!W11)) -> FLOAT | G11: =Sheet1!U11 -> In Shuttle Pre-Align Score 인터락 세팅값
A12: =Sheet1!A12 -> 10010 | B12: =Sheet1!C12 -> IN_SHUTTLE_P1_PRE_ALIGN_CELL_ID | C12: =IFERROR(IF(OR(LEN(TRIM(Sheet1!G12))=0, Sheet1!G12="N/A"), "-", Sheet1!G12),"-") -> - | D12: =IFERROR(IF(OR(LEN(TRIM(Sheet1!I12))=0, Sheet1!I12="N/A"), "-", Sheet1!I12),"-") -> - | E12: =IFERROR(IF(OR(LEN(TRIM(Sheet1!K12))=0, Sheet1!K12="N/A"), "-", Sheet1!K12),"-") -> - | F12: =IF(Sheet1!W12="STRING","ASCII",IF(Sheet1!W12="INTEGER","FLOAT",Sheet1!W12)) -> ASCII | G12: =Sheet1!U12 -> In Shuttle P1 Pre-Align Cell ID
A13: =Sheet1!A13 -> 10011 | B13: =Sheet1!C13 -> IN_SHUTTLE_P1_PRE_ALIGN_STEP_ID | C13: =IFERROR(IF(OR(LEN(TRIM(Sheet1!G13))=0, Sheet1!G13="N/A"), "-", Sheet1!G13),"-") -> - | D13: =IFERROR(IF(OR(LEN(TRIM(Sheet1!I13))=0, Sheet1!I13="N/A"), "-", Sheet1!I13),"-") -> 0 | E13: =IFERROR(IF(OR(LEN(TRIM(Sheet1!K13))=0, Sheet1!K13="N/A"), "-", Sheet1!K13),"-") -> 2 | F13: =IF(Sheet1!W13="STRING","ASCII",IF(Sheet1!W13="INTEGER","FLOAT",Sheet1!W13)) -> FLOAT | G13: =Sheet1!U13 -> In Shuttle P1 Pre-Align Step ID
... A81: =Sheet1!A81 -> 0 | B81: =Sheet1!C81 -> 0 | C81: =IFERROR(IF(OR(LEN(TRIM(Sheet1!G81))=0, Sheet1!G81="N/A"), "-", Sheet1!G81),"-") -> - | D81: =IFERROR(IF(OR(LEN(TRIM(Sheet1!I81))=0, Sheet1!I81="N/A"), "-", Sheet1!I81),"-") -> - | E81: =IFERROR(IF(OR(LEN(TRIM(Sheet1!K81))=0, Sheet1!K81="N/A"), "-", Sheet1!K81),"-") -> - | F81: =IF(Sheet1!W81="STRING","ASCII",IF(Sheet1!W81="INTEGER","FLOAT",Sheet1!W81)) -> 0 | G81: =Sheet1!U81 -> 0
